Workbook

Sheet المخازن الفرعيه
M2: يناير 2026
E6: شركة اورشاب لتعدين الذهب
E7: المخازن 2025
K8: الكمية
B9: متسلسل | C9: المخزن | D9: القسم | E9: اسم الصنف عربي | F9: النوع | G9: اسم الصنف E | H9: رقم الصنف | I9: الرف - الصندوق | J9: كود الصنف | K9: الرصيد الافتتاحي | L9: الوارد | M9: المنصرف | N9: الرصيد الحالي | O9: الفعلي | P9: الجرد
B10: 1 | C10: فرعي (2) | D10: السباكة | E10: 1.1\4" ماسورة PPR | F10: قطعه | H10: 1.1\4" ماسورة PPR | I10: فرعي2 | J10: C000001 | K10: 16 | L10: =+SUMIF('حركه المخزن الرئيسي اليوميه'!$F:$F,$H:$H,'حركه المخزن الرئيسي اليوميه'!$H:$H) -> 0 | M10: =+SUMIF('حركه المخزن الرئيسي اليوميه'!$F:$F,$H:$H,'حركه المخزن الرئيسي اليوميه'!$I:$I) -> 0 | N10: =+K10+L10-M10 -> 16 | O10: =+N10 -> 16 | P10: =+N10-O10 -> 0
B11: 2 | C11: فرعي (2) | D11: السباكة | E11: ماسورة pvc | F11: فطعة | H11: ماسورة 4 بوصة pvc | I11: فرعي2 | J11: C000002 | K11: 9 | L11: =+SUMIF('حركه المخزن الرئيسي اليوميه'!$F:$F,$H:$H,'حركه المخزن الرئيسي اليوميه'!$H:$H) -> 0 | M11: =+SUMIF('حركه المخزن الرئيسي اليوميه'!$F:$F,$H:$H,'حركه المخزن الرئيسي اليوميه'!$I:$I) -> 0 | N11: =+K11+L11-M11 -> 9 | O11: =+N11 -> 9 | P11: =+N11-O11 -> 0
B12: 3 | C12: فرعي (2) | D12: الابار | E12: ماسورة فلتر (بلاستك) 6 بوصة طول 6متر | F12: قطعة | G12: Plastic Pipe | H12: ماسورة فلتر (بلاستك) 6 بوصة طول 6متر | I12: فرعي2 | J12: C000003 | K12: 11 | L12: =+SUMIF('حركه المخزن الرئيسي اليوميه'!$F:$F,$H:$H,'حركه المخزن الرئيسي اليوميه'!$H:$H) -> 0 | M12: =+SUMIF('حركه المخزن الرئيسي اليوميه'!$F:$F,$H:$H,'حركه المخزن الرئيسي اليوميه'!$I:$I) -> 0 | N12: =+K12+L12-M12 -> 11 | O12: =+N12 -> 11 | P12: =+N12-O12 -> 0
B13: 4 | C13: فرعي (2) | D13: الابار | E13: ماسورة بلاستيك صغيره -الابار | F13: قطعة | H13: ماسورة بلاستيك صغيره -الابار | I13: فرعي2 | J13: C000004 | K13: 47 | L13: =+SUMIF('حركه المخزن الرئيسي اليوميه'!$F:$F,$H:$H,'حركه المخزن الرئيسي اليوميه'!$H:$H) -> 0 | M13: =+SUMIF('حركه المخزن الرئيسي اليوميه'!$F:$F,$H:$H,'حركه المخزن الرئيسي اليوميه'!$I:$I) -> 0 | N13: =+K13+L13-M13 -> 47 | O13: =+N13 -> 47 | P13: =+N13-O13 -> 0
B14: 5 | C14: فرعي (2) | D14: السباكة | E14: تي pvc | F14: فطعة | H14: تي 4بوصة pvc | I14: فرعي2 | J14: C000005 | K14: 13 | L14: =+SUMIF('حركه المخزن الرئيسي اليوميه'!$F:$F,$H:$H,'حركه المخزن الرئيسي اليوميه'!$H:$H) -> 0 | M14: =+SUMIF('حركه المخزن الرئيسي اليوميه'!$F:$F,$H:$H,'حركه المخزن الرئيسي اليوميه'!$I:$I) -> 0 | N14: =+K14+L14-M14 -> 13 | O14: =+N14 -> 13 | P14: =+N14-O14 -> 0
B15: 6 | C15: فرعي (2) | D15: السباكة | E15: جلبة مخفض pvc | F15: فطعة | H15: جلبة مخفض 6" - 4 " pvc | I15: فرعي2 | J15: C000006 | K15: 4 | L15: =+SUMIF('حركه المخزن الرئيسي اليوميه'!$F:$F,$H:$H,'حركه المخزن الرئيسي اليوميه'!$H:$H) -> 0 | M15: =+SUMIF('حركه المخزن الرئيسي اليوميه'!$F:$F,$H:$H,'حركه المخزن الرئيسي اليوميه'!$I:$I) -> 0 | N15: =+K15+L15-M15 -> 4 | O15: =+N15 -> 4 | P15: =+N15-O15 -> 0
B16: 7 | C16: فرعي (2) | D16: السباكة | E16: تي pvc | F16: فطعة | H16: تي 6 بوصة pvc | I16: فرعي2 | J16: C000007 | K16: 7 | L16: =+SUMIF('حركه المخزن الرئيسي اليوميه'!$F:$F,$H:$H,'حركه المخزن الرئيسي اليوميه'!$H:$H) -> 0 | M16: =+SUMIF('حركه المخزن الرئيسي اليوميه'!$F:$F,$H:$H,'حركه المخزن الرئيسي اليوميه'!$I:$I) -> 0 | N16: =+K16+L16-M16 -> 7 | O16: =+N16 -> 7 | P16: =+N16-O16 -> 0
B17: 8 | C17: فرعي (2) | D17: السباكة | E17: كوع pvc | F17: فطعة | H17: كوع 4بوصة pvc زاوية قائمة | I17: فرعي2 | J17: C000008 | K17: 12 | L17: =+SUMIF('حركه المخزن الرئيسي اليوميه'!$F:$F,$H:$H,'حركه المخزن الرئيسي اليوميه'!$H:$H) -> 0 | M17: =+SUMIF('حركه المخزن الرئيسي اليوميه'!$F:$F,$H:$H,'حركه المخزن الرئيسي اليوميه'!$I:$I) -> 0 | N17: =+K17+L17-M17 -> 12 | O17: =+N17 -> 12 | P17: =+N17-O17 -> 0
B18: 9 | C18: فرعي (2) | D18: السباكة | E18: كوع pvc | F18: فطعة | H18: كوع 6بوصة pvc زاوية قائمة | I18: فرعي2 | J18: C000009 | K18: 4 | L18: =+SUMIF('حركه المخزن الرئيسي اليوميه'!$F:$F,$H:$H,'حركه المخزن الرئيسي اليوميه'!$H:$H) -> 0 | M18: =+SUMIF('حركه المخزن الرئيسي اليوميه'!$F:$F,$H:$H,'حركه المخزن الرئيسي اليوميه'!$I:$I) -> 0 | N18: =+K18+L18-M18 -> 4 | O18: =+N18 -> 4 | P18: =+N18-O18 -> 0
B19: 10 | C19: فرعي (2) | D19: المصنع | E19: اسكرين بلاستك (التنوكة) | F19: لفه | G19: Plastic Screen - Tanks | H19: اسكرين بلاستك (التنوكة) | I19: فرعي2 | J19: C000010 | K19: 16 | L19: =+SUMIF('حركه المخزن الرئيسي اليوميه'!$F:$F,$H:$H,'حركه المخزن الرئيسي اليوميه'!$H:$H) -> 0 | M19: =+SUMIF('حركه المخزن الرئيسي اليوميه'!$F:$F,$H:$H,'حركه المخزن الرئيسي اليوميه'!$I:$I) -> 0 | N19: =+K19+L19-M19 -> 16 | O19: =+N19 -> 16 | P19: =+N19-O19 -> 0
B20: 11 | C20: فرعي (2) | D20: السباكة | E20: ماسورة pvc | F20: فطعة | H20: ماسورة 6 بوصة pvc | I20: فرعي2 | J20: C000011 | K20: 5 | L20: =+SUMIF('حركه المخزن الرئيسي اليوميه'!$F:$F,$H:$H,'حركه المخزن الرئيسي اليوميه'!$H:$H) -> 0 | M20: =+SUMIF('حركه المخزن الرئيسي اليوميه'!$F:$F,$H:$H,'حركه المخزن الرئيسي اليوميه'!$I:$I) -> 0 | N20: =+K20+L20-M20 -> 5 | O20: =+N20 -> 5 | P20: =+N20-O20 -> 0
B21: 12 | C21: فرعي (2) | D21: السباكة | E21: ماسورة PPR | F21: قطعة | G21: PPR Pipe | H21: 4" ماسورة PPR | I21: فرعي2 | J21: C000012 | K21: 4 | L21: =+SUMIF('حركه المخزن الرئيسي اليوميه'!$F:$F,$H:$H,'حركه المخزن الرئيسي اليوميه'!$H:$H) -> 0 | M21: =+SUMIF('حركه المخزن الرئيسي اليوميه'!$F:$F,$H:$H,'حركه المخزن الرئيسي اليوميه'!$I:$I) -> 0 | N21: =+K21+L21-M21 -> 4 | O21: =+N21 -> 4 | P21: =+N21-O21 -> 0
B22: 13 | C22: فرعي (2) | D22: السباكة | E22: 2" PPR ماسورة | F22: قطعة | G22: HOSE PPR 2" | H22: 2" PPR ماسورة | I22: فرعي2 | J22: C000013 | K22: 3 | L22: =+SUMIF('حركه المخزن الرئيسي اليوميه'!$F:$F,$H:$H,'حركه المخزن الرئيسي اليوميه'!$H:$H) -> 0 | M22: =+SUMIF('حركه المخزن الرئيسي اليوميه'!$F:$F,$H:$H,'حركه المخزن الرئيسي اليوميه'!$I:$I) -> 0 | N22: =+K22+L22-M22 -> 3 | O22: =+N22 -> 3 | P22: =+N22-O22 -> 0
B23: 14 | C23: فرعي (1) | D23: المصنع | E23: كوع حديد لحام 3 بوصة DN65 | F23: قطعة | G23: Welding Iron elbow 3" | H23: كوع حديد لحام 3 بوصة DN65 | I23: R | J23: C000014 | K23: 22 | L23: =+SUMIF('حركه المخزن الرئيسي اليوميه'!$F:$F,$H:$H,'حركه المخزن الرئيسي اليوميه'!$H:$H) -> 0 | M23: =+SUMIF('حركه المخزن الرئيسي اليوميه'!$F:$F,$H:$H,'حركه المخزن الرئيسي اليوميه'!$I:$I) -> 0 | N23: =+K23+L23-M23 -> 22 | O23: =+N23 -> 22 | P23: =+N23-O23 -> 0
B24: 15 | C24: فرعي (1) | D24: المصنع | E24: كوع حديد لحام 4 بوصة DN100 | F24: قطعة | G24: Welding Iron elbow 4" | H24: كوع حديد لحام 4 بوصة DN100 | I24: R | J24: C000015 | K24: 0 | L24: =+SUMIF('حركه المخزن الرئيسي اليوميه'!$F:$F,$H:$H,'حركه المخزن الرئيسي اليوميه'!$H:$H) -> 0 | M24: =+SUMIF('حركه المخزن الرئيسي اليوميه'!$F:$F,$H:$H,'حركه المخزن الرئيسي اليوميه'!$I:$I) -> 0 | N24: =+K24+L24-M24 -> 0 | O24: =+N24 -> 0 | P24: =+N24-O24 -> 0
B25: 16 | C25: فرعي (1) | D25: المصنع | E25: كوع حديد لحام 6 بوصة DN150 | F25: قطعة | G25: Welding Iron elbow 6" | H25: كوع حديد لحام 6 بوصة DN150 | I25: R | J25: C000016 | K25: 17 | L25: =+SUMIF('حركه المخزن الرئيسي اليوميه'!$F:$F,$H:$H,'حركه المخزن الرئيسي اليوميه'!$H:$H) -> 0 | M25: =+SUMIF('حركه المخزن الرئيسي اليوميه'!$F:$F,$H:$H,'حركه المخزن الرئيسي اليوميه'!$I:$I) -> 0 | N25: =+K25+L25-M25 -> 17 | O25: =+N25 -> 17 | P25: =+N25-O25 -> 0
B26: 17 | C26: فرعي (1) | D26: المصنع | E26: كوع حديد لحام 5 بوصة | F26: قطعة | G26: Welding Iron elbow 5" | H26: كوع حديد لحام 5 بوصة | I26: R | J26: C000017 | K26: 3 | L26: =+SUMIF('حركه المخزن الرئيسي اليوميه'!$F:$F,$H:$H,'حركه المخزن الرئيسي اليوميه'!$H:$H) -> 0 | M26: =+SUMIF('حركه المخزن الرئيسي اليوميه'!$F:$F,$H:$H,'حركه المخزن الرئيسي اليوميه'!$I:$I) -> 0 | N26: =+K26+L26-M26 -> 3 | O26: =+N26 -> 3 | P26: =+N26-O26 -> 0
B27: 18 | C27: فرعي (1) | D27: المصنع | E27: كوع حديد لحام 8" DN200 | F27: قطعة | G27: ELBOW IRON | H27: كوع حديد لحام 8" DN200 | I27: R | J27: C000018 | K27: 19 | L27: =+SUMIF('حركه المخزن الرئيسي اليوميه'!$F:$F,$H:$H,'حركه المخزن الرئيسي اليوميه'!$H:$H) -> 0 | M27: =+SUMIF('حركه المخزن الرئيسي اليوميه'!$F:$F,$H:$H,'حركه المخزن الرئيسي اليوميه'!$I:$I) -> 0 | N27: =+K27+L27-M27 -> 19 | O27: =+N27 -> 19 | P27: =+N27-O27 -> 0
B28: 19 | C28: فرعي (1) | D28: المصنع | E28: بلف بلية | F28: قطعة | G28: Ball Valve | H28: DN125 بلف بلية | I28: A-9 | J28: C000019 | K28: 5 | L28: =+SUMIF('حركه المخزن الرئيسي اليوميه'!$F:$F,$H:$H,'حركه المخزن الرئيسي اليوميه'!$H:$H) -> 0 | M28: =+SUMIF('حركه المخزن الرئيسي اليوميه'!$F:$F,$H:$H,'حركه المخزن الرئيسي اليوميه'!$I:$I) -> 1 | N28: =+K28+L28-M28 -> 4 | O28: =+N28 -> 4 | P28: =+N28-O28 -> 0
B29: 20 | C29: فرعي (1) | D29: المصنع | E29: بلف سايكلون | F29: قطعة | G29: Valve | H29: DN 80 | I29: A-9 | J29: C000020 | K29: 10 | L29: =+SUMIF('حركه المخزن الرئيسي اليوميه'!$F:$F,$H:$H,'حركه المخزن الرئيسي اليوميه'!$H:$H) -> 0 | M29: =+SUMIF('حركه المخزن الرئيسي اليوميه'!$F:$F,$H:$H,'حركه المخزن الرئيسي اليوميه'!$I:$I) -> 3 | N29: =+K29+L29-M29 -> 7 | O29: =+N29 -> 7 | P29: =+N29-O29 -> 0
B30: 21 | C30: فرعي (1) | D30: المصنع | E30: بلف رداخ | F30: قطعة | G30: Valve | H30: PN50 | I30: A-8 | J30: C000021 | K30: 3 | L30: =+SUMIF('حركه المخزن الرئيسي اليوميه'!$F:$F,$H:$H,'حركه المخزن الرئيسي اليوميه'!$H:$H) -> 0 | M30: =+SUMIF('حركه المخزن الرئيسي اليوميه'!$F:$F,$H:$H,'حركه المخزن الرئيسي اليوميه'!$I:$I) -> 0 | N30: =+K30+L30-M30 -> 3 | O30: =+N30 -> 3 | P30: =+N30-O30 -> 0
B31: 22 | C31: فرعي (1) | D31: المصنع | E31: بلف بلية | F31: قطعة | G31: Ball Valve | H31: DN80 بلف بلية | I31: A-9 | J31: C000022 | K31: 2 | L31: =+SUMIF('حركه المخزن الرئيسي اليوميه'!$F:$F,$H:$H,'حركه المخزن الرئيسي اليوميه'!$H:$H) -> 0 | M31: =+SUMIF('حركه المخزن الرئيسي اليوميه'!$F:$F,$H:$H,'حركه المخزن الرئيسي اليوميه'!$I:$I) -> 0 | N31: =+K31+L31-M31 -> 2 | O31: =+N31 -> 2 | P31: =+N31-O31 -> 0
B32: 23 | C32: فرعي (1) | D32: المصنع | E32: بلف رداخ | F32: قطعة | G32: Valve | H32: PN80 | I32: A-8 | J32: C000023 | K32: 25 | L32: =+SUMIF('حركه المخزن الرئيسي اليوميه'!$F:$F,$H:$H,'حركه المخزن الرئيسي اليوميه'!$H:$H) -> 0 | M32: =+SUMIF('حركه المخزن الرئيسي اليوميه'!$F:$F,$H:$H,'حركه المخزن الرئيسي اليوميه'!$I:$I) -> 0 | N32: =+K32+L32-M32 -> 25 | O32: =+N32 -> 25 | P32: =+N32-O32 -> 0
... B35: 26 | C35: فرعي (1) | D35: المصنع | E35: بلف سايكلون | F35: قطعة | G35: Valve | H35: DN 100/16 | I35: A-14 | J35: C000026 | K35: 2 | L35: =+SUMIF('حركه المخزن الرئيسي اليوميه'!$F:$F,$H:$H,'حركه المخزن الرئيسي اليوميه'!$H:$H) -> 0 | M35: =+SUMIF('حركه المخزن الرئيسي اليوميه'!$F:$F,$H:$H,'حركه المخزن الرئيسي اليوميه'!$I:$I) -> 0 | N35: =+K35+L35-M35 -> 2 | O35: =+N35 -> 2 | P35: =+N35-O35 -> 0
B36: 27 | C36: فرعي (1) | D36: المصنع | E36: بلف بلية | F36: قطعة | H36: DN25 بلف بلية | I36: A-7 | J36: C000027 | K36: 47 | L36: =+SUMIF('حركه المخزن الرئيسي اليوميه'!$F:$F,$H:$H,'حركه المخزن الرئيسي اليوميه'!$H:$H) -> 0 | M36: =+SUMIF('حركه المخزن الرئيسي اليوميه'!$F:$F,$H:$H,'حركه المخزن الرئيسي اليوميه'!$I:$I) -> 0 | N36: =+K36+L36-M36 -> 47 | O36: =+N36 -> 47 | P36: =+N36-O36 -> 0
B37: 32 | C37: فرعي (1) | D37: المصنع | E37: بلف بلية | F37: قطعة | H37: DN15 بلف بلية | I37: A-7 | J37: C000028 | K37: 45 | L37: =+SUMIF('حركه المخزن الرئيسي اليوميه'!$F:$F,$H:$H,'حركه المخزن الرئيسي اليوميه'!$H:$H) -> 0 | M37: =+SUMIF('حركه المخزن الرئيسي اليوميه'!$F:$F,$H:$H,'حركه المخزن الرئيسي اليوميه'!$I:$I) -> 0 | N37: =+K37+L37-M37 -> 45 | O37: =+N37 -> 45 | P37: =+N37-O37 -> 0
B38: 33 | C38: فرعي (1) | D38: المصنع | E38: بلف | F38: قطعة | G38: Valve | H38: DN65 | I38: A-14 | J38: C000029 | K38: 14 | L38: =+SUMIF('حركه المخزن الرئيسي اليوميه'!$F:$F,$H:$H,'حركه المخزن الرئيسي اليوميه'!$H:$H) -> 0 | M38: =+SUMIF('حركه المخزن الرئيسي اليوميه'!$F:$F,$H:$H,'حركه المخزن الرئيسي اليوميه'!$I:$I) -> 0 | N38: =+K38+L38-M38 -> 14 | O38: =+N38 -> 14 | P38: =+N38-O38 -> 0
B39: 34 | C39: فرعي (1) | D39: المصنع | E39: بلف | F39: قطعة | G39: Valve | H39: DN25 | I39: A-7 | J39: C000030 | K39: 7 | L39: =+SUMIF('حركه المخزن الرئيسي اليوميه'!$F:$F,$H:$H,'حركه المخزن الرئيسي اليوميه'!$H:$H) -> 0 | M39: =+SUMIF('حركه المخزن الرئيسي اليوميه'!$F:$F,$H:$H,'حركه المخزن الرئيسي اليوميه'!$I:$I) -> 0 | N39: =+K39+L39-M39 -> 7 | O39: =+N39 -> 7 | P39: =+N39-O39 -> 0
B40: 35 | C40: فرعي (1) | D40: المصنع | E40: بلف | F40: قطعة | G40: Valve | H40: DN32 | I40: A-7 | J40: C000031 | K40: 15 | L40: =+SUMIF('حركه المخزن الرئيسي اليوميه'!$F:$F,$H:$H,'حركه المخزن الرئيسي اليوميه'!$H:$H) -> 0 | M40: =+SUMIF('حركه المخزن الرئيسي اليوميه'!$F:$F,$H:$H,'حركه المخزن الرئيسي اليوميه'!$I:$I) -> 0 | N40: =+K40+L40-M40 -> 15 | O40: =+N40 -> 15 | P40: =+N40-O40 -> 0
B41: 36 | C41: فرعي (1) | D41: المصنع | E41: بلف عادي | F41: قطعة | G41: Valve | H41: DN50 بلف | I41: A-13 | J41: C000032 | K41: 35 | L41: =+SUMIF('حركه المخزن الرئيسي اليوميه'!$F:$F,$H:$H,'حركه المخزن الرئيسي اليوميه'!$H:$H) -> 0 | M41: =+SUMIF('حركه المخزن الرئيسي اليوميه'!$F:$F,$H:$H,'حركه المخزن الرئيسي اليوميه'!$I:$I) -> 2 | N41: =+K41+L41-M41 -> 33 | O41: =+N41 -> 33 | P41: =+N41-O41 -> 0
B42: 37 | C42: فرعي (1) | D42: المصنع | E42: بلف | F42: قطعة | G42: Valve | H42: DN40 | I42: A-7 | J42: C000033 | K42: 14 | L42: =+SUMIF('حركه المخزن الرئيسي اليوميه'!$F:$F,$H:$H,'حركه المخزن الرئيسي اليوميه'!$H:$H) -> 0 | M42: =+SUMIF('حركه المخزن الرئيسي اليوميه'!$F:$F,$H:$H,'حركه المخزن الرئيسي اليوميه'!$I:$I) -> 0 | N42: =+K42+L42-M42 -> 14 | O42: =+N42 -> 14 | P42: =+N42-O42 -> 0
B43: 38 | C43: فرعي (1) | D43: المصنع | E43: بلف | F43: قطعة | G43: Valve | H43: DN80 بلف | I43: A-13 | J43: C000034 | K43: 5 | L43: =+SUMIF('حركه المخزن الرئيسي اليوميه'!$F:$F,$H:$H,'حركه المخزن الرئيسي اليوميه'!$H:$H) -> 0 | M43: =+SUMIF('حركه المخزن الرئيسي اليوميه'!$F:$F,$H:$H,'حركه المخزن الرئيسي اليوميه'!$I:$I) -> 1 | N43: =+K43+L43-M43 -> 4 | O43: =+N43 -> 4 | P43: =+N43-O43 -> 0
B44: 39 | C44: فرعي (1) | D44: المصنع | E44: DN 100/16 بلف عادي | F44: قطعة | G44: Valve | H44: DN 100/16 بلف عادي | I44: A-13 | J44: C000035 | K44: 4 | L44: =+SUMIF('حركه المخزن الرئيسي اليوميه'!$F:$F,$H:$H,'حركه المخزن الرئيسي اليوميه'!$H:$H) -> 0 | M44: =+SUMIF('حركه المخزن الرئيسي اليوميه'!$F:$F,$H:$H,'حركه المخزن الرئيسي اليوميه'!$I:$I) -> 2 | N44: =+K44+L44-M44 -> 2 | O44: =+N44 -> 2 | P44: =+N44-O44 -> 0
B45: 40 | C45: فرعي (1) | D45: المصنع | E45: lower cone line | F45: قطعة | G45: lower cone line | H45: بلاستيك lower cone line | I45: A-2 | J45: C000036 | K45: 2 | L45: =+SUMIF('حركه المخزن الرئيسي اليوميه'!$F:$F,$H:$H,'حركه المخزن الرئيسي اليوميه'!$H:$H) -> 0 | M45: =+SUMIF('حركه المخزن الرئيسي اليوميه'!$F:$F,$H:$H,'حركه المخزن الرئيسي اليوميه'!$I:$I) -> 0 | N45: =+K45+L45-M45 -> 2 | O45: =+N45 -> 2 | P45: =+N45-O45 -> 0
B46: 41 | C46: فرعي (1) | D46: المصنع | E46: كوع فلنشة سايكلون | F46: قطعة | G46: Elbow Flange | H46: كوع فلنشة سايكلون | I46: A-4 | J46: C000037 | K46: 2 | L46: =+SUMIF('حركه المخزن الرئيسي اليوميه'!$F:$F,$H:$H,'حركه المخزن الرئيسي اليوميه'!$H:$H) -> 0 | M46: =+SUMIF('حركه المخزن الرئيسي اليوميه'!$F:$F,$H:$H,'حركه المخزن الرئيسي اليوميه'!$I:$I) -> 0 | N46: =+K46+L46-M46 -> 2 | O46: =+N46 -> 2 | P46: =+N46-O46 -> 0
...

Sheet الساحة
M2: يناير 2026
J3: ذ
E6: شركة اورشاب لتعدين الذهب
E7: المخازن 2025
K8: الكمية | R8: ملاحظات
B9: متسلسل | C9: المخزن | D9: القسم | E9: اسم الصنف عربي | F9: النوع | G9: اسم الصنف E | H9: رقم الصنف | I9: الرف - الصندوق | J9: كود الصنف | K9: الرصيد الافتتاحي | L9: الوارد | M9: المنصرف | N9: الرصيد الحالي | O9: الفلي | P9: الجرد
B10: 3 | C10: الساحة | D10: المصنع | E10: سلك شايك ( شرشر ) | F10: قطعة | G10: Barbed wire | H10: سلك شايك ( شرشر ) | I10: الساحة"2" | J10: D000001 | K10: 9 | L10: =+SUMIF('حركه المخزن الرئيسي اليوميه'!$F:$F,$H:$H,'حركه المخزن الرئيسي اليوميه'!$H:$H) -> 0 | M10: =+SUMIF('حركه المخزن الرئيسي اليوميه'!$F:$F,$H:$H,'حركه المخزن الرئيسي اليوميه'!$I:$I) -> 0 | N10: =+K10+L10-M10 -> 9 | O10: =+N10 -> 9 | P10: =+N10-O10 -> 0
B11: 4 | C11: الساحة | D11: الصيانه | E11: خوصة 6 متر | F11: قطعة | G11: iron Wicker | H11: خوصة 6 متر | I11: الساحة"1" | J11: D000002 | K11: 0 | L11: =+SUMIF('حركه المخزن الرئيسي اليوميه'!$F:$F,$H:$H,'حركه المخزن الرئيسي اليوميه'!$H:$H) -> 0 | M11: =+SUMIF('حركه المخزن الرئيسي اليوميه'!$F:$F,$H:$H,'حركه المخزن الرئيسي اليوميه'!$I:$I) -> 0 | N11: =+K11+L11-M11 -> 0 | O11: =+N11 -> 0 | P11: =+N11-O11 -> 0
B12: 5 | C12: الساحة | D12: محطه التحليه | E12: طلمبة ضغط عالي الخلية ( راسية ) | F12: قطعة | H12: طلمبة ضغط عالي الخلية ( راسية ) | I12: الساحة"1" | J12: D000003 | K12: 0 | L12: =+SUMIF('حركه المخزن الرئيسي اليوميه'!$F:$F,$H:$H,'حركه المخزن الرئيسي اليوميه'!$H:$H) -> 0 | M12: =+SUMIF('حركه المخزن الرئيسي اليوميه'!$F:$F,$H:$H,'حركه المخزن الرئيسي اليوميه'!$I:$I) -> 0 | N12: =+K12+L12-M12 -> 0 | O12: =+N12 -> 0 | P12: =+N12-O12 -> 0
B13: 6 | C13: الساحة | D13: الكهرباء | E13: جهاز كهربائي فرن الصهر | F13: قطعة | H13: جهاز كهربائي فرن الصهر | I13: الاسمنت | J13: D000004 | K13: 0 | L13: =+SUMIF('حركه المخزن الرئيسي اليوميه'!$F:$F,$H:$H,'حركه المخزن الرئيسي اليوميه'!$H:$H) -> 0 | M13: =+SUMIF('حركه المخزن الرئيسي اليوميه'!$F:$F,$H:$H,'حركه المخزن الرئيسي اليوميه'!$I:$I) -> 0 | N13: =+K13+L13-M13 -> 0 | O13: =+N13 -> 0 | P13: =+N13-O13 -> 0
B14: 9 | C14: الساحة | D14: الكهرباء | E14: طبلون كهرباء البلور | F14: قطعة | G14: Electric Pannel | H14: طبلون البلور | I14: ساحه 1 | J14: D000005 | K14: 1 | L14: =+SUMIF('حركه المخزن الرئيسي اليوميه'!$F:$F,$H:$H,'حركه المخزن الرئيسي اليوميه'!$H:$H) -> 0 | M14: =+SUMIF('حركه المخزن الرئيسي اليوميه'!$F:$F,$H:$H,'حركه المخزن الرئيسي اليوميه'!$I:$I) -> 0 | N14: =+K14+L14-M14 -> 1 | O14: =+N14 -> 1 | P14: =+N14-O14 -> 0
B15: 10 | C15: الساحة | D15: الكهرباء | E15: فرن كهربائى (المعمل) | F15: فرن | G15: Lap Electric Oven | H15: فرن كهربائى (المعمل) | I15: R | J15: D000006 | K15: 0 | L15: =+SUMIF('حركه المخزن الرئيسي اليوميه'!$F:$F,$H:$H,'حركه المخزن الرئيسي اليوميه'!$H:$H) -> 0 | M15: =+SUMIF('حركه المخزن الرئيسي اليوميه'!$F:$F,$H:$H,'حركه المخزن الرئيسي اليوميه'!$I:$I) -> 0 | N15: =+K15+L15-M15 -> 0 | O15: =+N15 -> 0 | P15: =+N15-O15 -> 0
B16: 17 | C16: الساحة | D16: المصنع | E16: جلبة نحاس حجر الكسارة المتحرك | F16: فطعة | H16: جلبة نحاس حجر الكسارة المتحرك | I16: ساحه 1 | J16: D000007 | K16: 1 | L16: =+SUMIF('حركه المخزن الرئيسي اليوميه'!$F:$F,$H:$H,'حركه المخزن الرئيسي اليوميه'!$H:$H) -> 0 | M16: =+SUMIF('حركه المخزن الرئيسي اليوميه'!$F:$F,$H:$H,'حركه المخزن الرئيسي اليوميه'!$I:$I) -> 0 | N16: =+K16+L16-M16 -> 1 | O16: =+N16 -> 1 | P16: =+N16-O16 -> 0
B17: 18 | C17: الساحة | D17: السباكة | E17: بيبا كاملة | F17: فطعة | H17: بيبا 4 بوصة | I17: الاسمنت | J17: D000008 | K17: 0 | L17: =+SUMIF('حركه المخزن الرئيسي اليوميه'!$F:$F,$H:$H,'حركه المخزن الرئيسي اليوميه'!$H:$H) -> 0 | M17: =+SUMIF('حركه المخزن الرئيسي اليوميه'!$F:$F,$H:$H,'حركه المخزن الرئيسي اليوميه'!$I:$I) -> 0 | N17: =+K17+L17-M17 -> 0 | O17: =+N17 -> 0 | P17: =+N17-O17 -> 0
B18: 19 | C18: الساحة | D18: الكهرباء | E18: مولد PERKINS 400KVA | F18: فطعة | H18: مولد PERKINS 400KVA | I18: السكن | J18: D000009 | K18: 1 | L18: =+SUMIF('حركه المخزن الرئيسي اليوميه'!$F:$F,$H:$H,'حركه المخزن الرئيسي اليوميه'!$H:$H) -> 0 | M18: =+SUMIF('حركه المخزن الرئيسي اليوميه'!$F:$F,$H:$H,'حركه المخزن الرئيسي اليوميه'!$I:$I) -> 0 | N18: =+K18+L18-M18 -> 1 | O18: =+N18 -> 1 | P18: =+N18-O18 -> 0
B19: 20 | C19: الساحه | D19: السباكة | E19: كدوس pvc | F19: فطعة | H19: كدوس 4بوصة pvc | I19: الاسمنت | J19: D000010 | K19: 0 | L19: =+SUMIF('حركه المخزن الرئيسي اليوميه'!$F:$F,$H:$H,'حركه المخزن الرئيسي اليوميه'!$H:$H) -> 0 | M19: =+SUMIF('حركه المخزن الرئيسي اليوميه'!$F:$F,$H:$H,'حركه المخزن الرئيسي اليوميه'!$I:$I) -> 0 | N19: =+K19+L19-M19 -> 0 | O19: =+N19 -> 0 | P19: =+N19-O19 -> 0
B20: 21 | J20: D000011 | K20: 0 | L20: =+SUMIF('حركه المخزن الرئيسي اليوميه'!$F:$F,$H:$H,'حركه المخزن الرئيسي اليوميه'!$H:$H) -> 0 | M20: =+SUMIF('حركه المخزن الرئيسي اليوميه'!$F:$F,$H:$H,'حركه المخزن الرئيسي اليوميه'!$I:$I) -> 0 | N20: =+K20+L20-M20 -> 0 | O20: =+N20 -> 0 | P20: =+N20-O20 -> 0
B21: 22 | C21: الساحة | D21: المصنع | E21: End Liner بلتة طواحين مثلثة | F21: قطعة | G21: End Liner | H21: End Liner بلتة طواحين مثلثة | I21: الساحة"2" | J21: D000012 | K21: 17 | L21: =+SUMIF('حركه المخزن الرئيسي اليوميه'!$F:$F,$H:$H,'حركه المخزن الرئيسي اليوميه'!$H:$H) -> 0 | M21: =+SUMIF('حركه المخزن الرئيسي اليوميه'!$F:$F,$H:$H,'حركه المخزن الرئيسي اليوميه'!$I:$I) -> 0 | N21: =+K21+L21-M21 -> 17 | O21: =+N21 -> 17 | P21: =+N21-O21 -> 0
B22: 23 | C22: الساحة | D22: المصنع | E22: Large Liner 64 بلته طواحين | F22: قطعة | G22: Large Liner 64 | H22: Large Liner 64 | I22: الساحة"2" | J22: D000013 | K22: 120 | L22: =+SUMIF('حركه المخزن الرئيسي اليوميه'!$F:$F,$H:$H,'حركه المخزن الرئيسي اليوميه'!$H:$H) -> 0 | M22: =+SUMIF('حركه المخزن الرئيسي اليوميه'!$F:$F,$H:$H,'حركه المخزن الرئيسي اليوميه'!$I:$I) -> 0 | N22: =+K22+L22-M22 -> 120 | O22: =+N22 -> 120 | P22: =+N22-O22 -> 0
B23: 24 | C23: الساحة | D23: المصنع | E23: MiddLe Liner 59 بلته طواحين | F23: قطعة | G23: MiddLe Liner 59 | H23: MiddLe Liner 59 | I23: الساحة"2" | J23: D000014 | K23: 18 | L23: =+SUMIF('حركه المخزن الرئيسي اليوميه'!$F:$F,$H:$H,'حركه المخزن الرئيسي اليوميه'!$H:$H) -> 0 | M23: =+SUMIF('حركه المخزن الرئيسي اليوميه'!$F:$F,$H:$H,'حركه المخزن الرئيسي اليوميه'!$I:$I) -> 0 | N23: =+K23+L23-M23 -> 18 | O23: =+N23 -> 18 | P23: =+N23-O23 -> 0
B24: 25 | C24: الساحة | D24: المصنع | E24: فك كسارة | F24: قطعة | G24: Jaw Crusher | H24: HVZG190714E - XP20110(60*100 | I24: الساحة | J24: D000015 | K24: 0 | L24: =+SUMIF('حركه المخزن الرئيسي اليوميه'!$F:$F,$H:$H,'حركه المخزن الرئيسي اليوميه'!$H:$H) -> 0 | M24: =+SUMIF('حركه المخزن الرئيسي اليوميه'!$F:$F,$H:$H,'حركه المخزن الرئيسي اليوميه'!$I:$I) -> 0 | N24: =+K24+L24-M24 -> 0 | O24: =+N24 -> 0 | P24: =+N24-O24 -> 0
B25: 26 | C25: الساحة | D25: الصيانه | E25: اسطوانة اكسجين | F25: قطعة | G25: Oxygen Cylinder | H25: اسطوانة اكسجين | I25: الساحة"1" | J25: D000016 | K25: 0 | L25: =+SUMIF('حركه المخزن الرئيسي اليوميه'!$F:$F,$H:$H,'حركه المخزن الرئيسي اليوميه'!$H:$H) -> 0 | M25: =+SUMIF('حركه المخزن الرئيسي اليوميه'!$F:$F,$H:$H,'حركه المخزن الرئيسي اليوميه'!$I:$I) -> 0 | N25: =+K25+L25-M25 -> 0 | O25: =+N25 -> 0 | P25: =+N25-O25 -> 0
B26: 27 | C26: الساحة | D26: المصنع | E26: اسكرين هزاز ( الكسارة ) | F26: قطعة | G26: Double deck steel sheet | H26: اسكرين هزاز ( الكسارة ) | I26: الساحة"1" | J26: D000017 | K26: 11 | L26: =+SUMIF('حركه المخزن الرئيسي اليوميه'!$F:$F,$H:$H,'حركه المخزن الرئيسي اليوميه'!$H:$H) -> 0 | M26: =+SUMIF('حركه المخزن الرئيسي اليوميه'!$F:$F,$H:$H,'حركه المخزن الرئيسي اليوميه'!$I:$I) -> 0 | N26: =+K26+L26-M26 -> 11 | O26: =+N26 -> 11 | P26: =+N26-O26 -> 0
B27: 28 | C27: الساحة | D27: المصنع | E27: امبلير (طلمبة الطواحين) | F27: قطعة | G27: Impeller 4/3 - Ball Mill Grinder | H27: امبلير (طلمبة الطواحين) 6/4 | I27: الساحة"1" | J27: D000018 | K27: 2 | L27: =+SUMIF('حركه المخزن الرئيسي اليوميه'!$F:$F,$H:$H,'حركه المخزن الرئيسي اليوميه'!$H:$H) -> 0 | M27: =+SUMIF('حركه المخزن الرئيسي اليوميه'!$F:$F,$H:$H,'حركه المخزن الرئيسي اليوميه'!$I:$I) -> 0 | N27: =+K27+L27-M27 -> 2 | O27: =+N27 -> 2 | P27: =+N27-O27 -> 0
B28: 29 | C28: الساحة | D28: المصنع | E28: اير ليفتر(AIRLIFTER) - التنوكة | F28: قطعة | H28: اير ليفتر(AIRLIFTER) - التنوكة | I28: الساحة"2" | J28: D000019 | K28: 5 | L28: =+SUMIF('حركه المخزن الرئيسي اليوميه'!$F:$F,$H:$H,'حركه المخزن الرئيسي اليوميه'!$H:$H) -> 0 | M28: =+SUMIF('حركه المخزن الرئيسي اليوميه'!$F:$F,$H:$H,'حركه المخزن الرئيسي اليوميه'!$I:$I) -> 1 | N28: =+K28+L28-M28 -> 4 | O28: =+N28 -> 4 | P28: =+N28-O28 -> 0
B29: 30 | C29: الساحة | D29: الكهرباء | E29: حمالة كوابل الطاقة الشمسية (حديد) | F29: قطعة | G29: SunPower Cable Holder | H29: حمالة كوابل الطاقة الشمسية (حديد) | I29: الساحة"2" | J29: D000020 | K29: 18 | L29: =+SUMIF('حركه المخزن الرئيسي اليوميه'!$F:$F,$H:$H,'حركه المخزن الرئيسي اليوميه'!$H:$H) -> 0 | M29: =+SUMIF('حركه المخزن الرئيسي اليوميه'!$F:$F,$H:$H,'حركه المخزن الرئيسي اليوميه'!$I:$I) -> 0 | N29: =+K29+L29-M29 -> 18 | O29: =+N29 -> 18 | P29: =+N29-O29 -> 0
B30: 31 | C30: الساحة | D30: المعمل | E30: كسارة (المعمل) | F30: كسارة | G30: Jaw Crusher model (xp100*60) | H30: jaw crusher model (xp100*60) | I30: الساحة"1" | J30: D000021 | K30: 4 | L30: =+SUMIF('حركه المخزن الرئيسي اليوميه'!$F:$F,$H:$H,'حركه المخزن الرئيسي اليوميه'!$H:$H) -> 0 | M30: =+SUMIF('حركه المخزن الرئيسي اليوميه'!$F:$F,$H:$H,'حركه المخزن الرئيسي اليوميه'!$I:$I) -> 0 | N30: 4 | O30: =+N30 -> 4 | P30: =+N30-O30 -> 0
B31: 32 | C31: الساحة | D31: المصنع | E31: درج اسكرين التنوكة | F31: قطعة | G31: Tanks Screen Drawer | H31: درج اسكرين التنوكة | I31: الساحة"1" | J31: D000022 | K31: 25 | L31: =+SUMIF('حركه المخزن الرئيسي اليوميه'!$F:$F,$H:$H,'حركه المخزن الرئيسي اليوميه'!$H:$H) -> 0 | M31: =+SUMIF('حركه المخزن الرئيسي اليوميه'!$F:$F,$H:$H,'حركه المخزن الرئيسي اليوميه'!$I:$I) -> 0 | N31: =+K31+L31-M31 -> 25 | O31: =+N31 -> 25 | P31: =+N31-O31 -> 0
B32: 33 | C32: الساحة | D32: المعمل | E32: ربر طاحونة (المعمل) | F32: قطعة | G32: Lab Mill Rubber | H32: ربرsk100-3 | I32: الساحة | J32: D000023 | K32: 0 | L32: =+SUMIF('حركه المخزن الرئيسي اليوميه'!$F:$F,$H:$H,'حركه المخزن الرئيسي اليوميه'!$H:$H) -> 0 | M32: =+SUMIF('حركه المخزن الرئيسي اليوميه'!$F:$F,$H:$H,'حركه المخزن الرئيسي اليوميه'!$I:$I) -> 0 | N32: =+K32+L32-M32 -> 0 | O32: =+N32 -> 0 | P32: =+N32-O32 -> 0
B33: 34 | C33: الساحة | D33: المعمل | E33: طاحونة (المعمل) | F33: طاحونة | G33: Lab Mill | H33: crusher (sk-100) طاحونة (المعمل) | I33: الساحة"1" | J33: D000024 | K33: 2 | L33: =+SUMIF('حركه المخزن الرئيسي اليوميه'!$F:$F,$H:$H,'حركه المخزن الرئيسي اليوميه'!$H:$H) -> 0 | M33: =+SUMIF('حركه المخزن الرئيسي اليوميه'!$F:$F,$H:$H,'حركه المخزن الرئيسي اليوميه'!$I:$I) -> 0 | N33: 2 | O33: =+N33 -> 2 | P33: =+N33-O33 -> 0
B34: 35 | C34: الساحة | D34: المصنع | E34: اسكرين بلاستك كبير (هذاذ الكسارة) | F34: قطعة | G34: Plastic Screen - Crusher | H34: اسكرين بلاستك كبير (هذاذ الكسارة) | I34: الساحة"1" | J34: D000025 | K34: 0 | L34: =+SUMIF('حركه المخزن الرئيسي اليوميه'!$F:$F,$H:$H,'حركه المخزن الرئيسي اليوميه'!$H:$H) -> 0 | M34: =+SUMIF('حركه المخزن الرئيسي اليوميه'!$F:$F,$H:$H,'حركه المخزن الرئيسي اليوميه'!$I:$I) -> 0 | N34: =+K34+L34-M34 -> 0 | O34: =+N34 -> 0 | P34: =+N34-O34 -> 0
B35: 36 | C35: الساحة | D35: المصنع | E35: سكرين هزاز - حديد صغير | F35: قطعة | G35: Double deck steel sheet | H35: سكرين هزاز - حديد صغير | I35: الساحة | J35: D000026 | K35: 0 | L35: =+SUMIF('حركه المخزن الرئيسي اليوميه'!$F:$F,$H:$H,'حركه المخزن الرئيسي اليوميه'!$H:$H) -> 0 | M35: =+SUMIF('حركه المخزن الرئيسي اليوميه'!$F:$F,$H:$H,'حركه المخزن الرئيسي اليوميه'!$I:$I) -> 0 | N35: =+K35+L35-M35 -> 0 | O35: =+N35 -> 0 | P35: =+N35-O35 -> 0
B36: 37 | C36: الساحة | D36: المصنع | E36: اسكرين هزاز - حديد كبير (كسارة) | F36: قطعة | G36: Double deck steel sheet | H36: اسكرين هزاز - حديد كبير (كسارة) | I36: الساحة | J36: D000027 | K36: 0 | L36: =+SUMIF('حركه المخزن الرئيسي اليوميه'!$F:$F,$H:$H,'حركه المخزن الرئيسي اليوميه'!$H:$H) -> 0 | M36: =+SUMIF('حركه المخزن الرئيسي اليوميه'!$F:$F,$H:$H,'حركه المخزن الرئيسي اليوميه'!$I:$I) -> 0 | N36: =+K36+L36-M36 -> 0 | O36: =+N36 -> 0 | P36: =+N36-O36 -> 0
B37: 38 | C37: الساحة | D37: المصنع | E37: سلك شايك ( حصيرة ) | F37: لفه | G37: Barbed wire | H37: سلك شايك ( حصيرة ) | I37: الساحة"2" | J37: D000028 | K37: 12 | L37: =+SUMIF('حركه المخزن الرئيسي اليوميه'!$F:$F,$H:$H,'حركه المخزن الرئيسي اليوميه'!$H:$H) -> 0 | M37: =+SUMIF('حركه المخزن الرئيسي اليوميه'!$F:$F,$H:$H,'حركه المخزن الرئيسي اليوميه'!$I:$I) -> 0 | N37: 12 | O37: =+N37 -> 12 | P37: =+N37-O37 -> 0
B38: 39 | C38: الساحة | D38: المعمل | E38: اسيال طاحونة (المعمل) | F38: قطعة | G38: Lab Mill Seal | H38: سيل sk100-3 | I38: الساحة | J38: D000029 | K38: 0 | L38: =+SUMIF('حركه المخزن الرئيسي اليوميه'!$F:$F,$H:$H,'حركه المخزن الرئيسي اليوميه'!$H:$H) -> 0 | M38: =+SUMIF('حركه المخزن الرئيسي اليوميه'!$F:$F,$H:$H,'حركه المخزن الرئيسي اليوميه'!$I:$I) -> 0 | N38: =+K38+L38-M38 -> 0 | O38: =+N38 -> 0 | P38: =+N38-O38 -> 0
B39: 40 | C39: الساحة | D39: المصنع | E39: اسكرين هزاز ( الطواحين ) | F39: قطعة | G39: Double deck steel sheet | H39: اسكرين هزاز ( الطواحين ) | I39: الساحة"1" | J39: D000030 | K39: 9 | L39: =+SUMIF('حركه المخزن الرئيسي اليوميه'!$F:$F,$H:$H,'حركه المخزن الرئيسي اليوميه'!$H:$H) -> 0 | M39: =+SUMIF('حركه المخزن الرئيسي اليوميه'!$F:$F,$H:$H,'حركه المخزن الرئيسي اليوميه'!$I:$I) -> 0 | N39: =+K39+L39-M39 -> 9 | O39: =+N39 -> 9 | P39: =+N39-O39 -> 0
B40: 41 | C40: الساحة | D40: المصنع | E40: امبلير (طلمبة الفلتر) | F40: قطعة | G40: Impeller 6/4 - Filter Pump | H40: امبلير (طلمبة الفلتر) 4/3 | I40: الساحة | J40: D000031 | K40: 0 | L40: =+SUMIF('حركه المخزن الرئيسي اليوميه'!$F:$F,$H:$H,'حركه المخزن الرئيسي اليوميه'!$H:$H) -> 0 | M40: =+SUMIF('حركه المخزن الرئيسي اليوميه'!$F:$F,$H:$H,'حركه المخزن الرئيسي اليوميه'!$I:$I) -> 0 | N40: =+K40+L40-M40 -> 0 | O40: =+N40 -> 0 | P40: =+N40-O40 -> 0
B41: 42 | C41: المكتب | D41: الخلية | E41: اختام ( اسيال قفل ) | F41: قطعة | H41: اختام ( اسيال قفل ) | I41: المكتب | J41: D000032 | K41: 31 | L41: =+SUMIF('حركه المخزن الرئيسي اليوميه'!$F:$F,$H:$H,'حركه المخزن الرئيسي اليوميه'!$H:$H) -> 0 | M41: =+SUMIF('حركه المخزن الرئيسي اليوميه'!$F:$F,$H:$H,'حركه المخزن الرئيسي اليوميه'!$I:$I) -> 0 | N41: =+K41+L41-M41 -> 31 | O41: =+N41 -> 31 | P41: =+N41-O41 -> 0
B42: 43 | C42: الساحة | D42: المصنع | E42: طلمبة فلتر كبيرة (عمودية) | F42: قطعة | G42: Vertical Filter Pump | H42: طلمبة فلتر كبيرة (عمودية) | I42: الساحة | J42: D000033 | K42: 0 | L42: =+SUMIF('حركه المخزن الرئيسي اليوميه'!$F:$F,$H:$H,'حركه المخزن الرئيسي اليوميه'!$H:$H) -> 0 | M42: =+SUMIF('حركه المخزن الرئيسي اليوميه'!$F:$F,$H:$H,'حركه المخزن الرئيسي اليوميه'!$I:$I) -> 0 | N42: =+K42+L42-M42 -> 0 | O42: =+N42 -> 0 | P42: =+N42-O42 -> 0
B43: 44 | C43: الساحة | D43: المصنع | E43: بلتة بلاستيك (الفلتر) | F43: قطعة | G43: Filter Plastic Plate | H43: بلتة بلاستيك (الفلتر) | I43: الساحة"2" | J43: D000034 | K43: 2 | L43: =+SUMIF('حركه المخزن الرئيسي اليوميه'!$F:$F,$H:$H,'حركه المخزن الرئيسي اليوميه'!$H:$H) -> 0 | M43: =+SUMIF('حركه المخزن الرئيسي اليوميه'!$F:$F,$H:$H,'حركه المخزن الرئيسي اليوميه'!$I:$I) -> 0 | N43: =+K43+L43-M43 -> 2 | O43: =+N43 -> 2 | P43: =+N43-O43 -> 0
...

Sheet الكهرباء
M2: 2026 يناير
E6: شركة اورشاب لتعدين الذهب
E7: المخازن 2025
I8: =I7+I6 -> 0 | K8: الكمية | R8: ملاحظات
B9: متسلسل | C9: المخزن | D9: القسم | E9: اسم الصنف عربي | F9: النوع | G9: اسم الصنف E | H9: رقم الصنف | I9: الرف - الصندوق | J9: كود الصنف | K9: الرصيد الافتتاحي | L9: الوارد | M9: المنصرف | N9: الرصيد الحالي | O9: الفعلي | P9: الجرد
B10: 1 | C10: الكهرباء | D10: الكهرباء | E10: علب توزيع (بلاستك | F10: قطعة | G10: PVC Electric wall Mounted Box | H10: علب توزيع (بلاستك | I10: A-1 | J10: B000001 | K10: 113 | L10: =+SUMIF('حركه المخزن الرئيسي اليوميه'!$F:$F,$H:$H,'حركه المخزن الرئيسي اليوميه'!$H:$H) -> 0 | M10: =+SUMIF('حركه المخزن الرئيسي اليوميه'!$F:$F,$H:$H,'حركه المخزن الرئيسي اليوميه'!$I:$I) -> 0 | N10: =+K10+L10-M10 -> 113 | O10: =+N10 -> 113 | P10: =+N10-O10 -> 0
B11: 2 | C11: الكهرباء | D11: مولدات | E11: ثيرموستات | F11: قطعة | G11: THERMOSTATE | H11: ثيرموستات KPR1645 | I11: A-1 | J11: B000002 | K11: 3 | L11: =+SUMIF('حركه المخزن الرئيسي اليوميه'!$F:$F,$H:$H,'حركه المخزن الرئيسي اليوميه'!$H:$H) -> 0 | M11: =+SUMIF('حركه المخزن الرئيسي اليوميه'!$F:$F,$H:$H,'حركه المخزن الرئيسي اليوميه'!$I:$I) -> 0 | N11: =+K11+L11-M11 -> 3 | O11: =+N11 -> 3 | P11: =+N11-O11 -> 0
B12: 3 | C12: الكهرباء | D12: مولدات | E12: ثيرموستات | F12: قطعة | G12: THERMOSTATE | H12: ثيرموستات 2.5 | I12: A-1 | J12: B000003 | K12: 3 | L12: =+SUMIF('حركه المخزن الرئيسي اليوميه'!$F:$F,$H:$H,'حركه المخزن الرئيسي اليوميه'!$H:$H) -> 0 | M12: =+SUMIF('حركه المخزن الرئيسي اليوميه'!$F:$F,$H:$H,'حركه المخزن الرئيسي اليوميه'!$I:$I) -> 0 | N12: =+K12+L12-M12 -> 3 | O12: =+N12 -> 3 | P12: =+N12-O12 -> 0
B13: 4 | C13: الكهرباء | D13: الكهرباء | E13: طلمبات مكيفات 4000 وحدة | F13: قطعة | G13: WATER PUMP | H13: طلمبات مكيفات 4000 وحدة | I13: A-2 | J13: B000004 | K13: 0 | L13: =+SUMIF('حركه المخزن الرئيسي اليوميه'!$F:$F,$H:$H,'حركه المخزن الرئيسي اليوميه'!$H:$H) -> 0 | M13: =+SUMIF('حركه المخزن الرئيسي اليوميه'!$F:$F,$H:$H,'حركه المخزن الرئيسي اليوميه'!$I:$I) -> 0 | N13: =+K13+L13-M13 -> 0 | O13: =+N13 -> 0 | P13: =+N13-O13 -> 0
B14: 5 | C14: الكهرباء | D14: الكهرباء | E14: علبه بلاستك بلكات | F14: قطعة | G14: PVC Electric wall Mounted Box | H14: علبه بلاستك بلكات | I14: A-2 | J14: B000005 | K14: 0 | L14: =+SUMIF('حركه المخزن الرئيسي اليوميه'!$F:$F,$H:$H,'حركه المخزن الرئيسي اليوميه'!$H:$H) -> 0 | M14: =+SUMIF('حركه المخزن الرئيسي اليوميه'!$F:$F,$H:$H,'حركه المخزن الرئيسي اليوميه'!$I:$I) -> 0 | N14: =+K14+L14-M14 -> 0 | O14: =+N14 -> 0 | P14: =+N14-O14 -> 0
B15: 6 | C15: الكهرباء | D15: الكهرباء | E15: C.T 1000/5 | F15: قطعة | H15: C.T 1000/5 | I15: A-4 | J15: B000006 | K15: 17 | L15: =+SUMIF('حركه المخزن الرئيسي اليوميه'!$F:$F,$H:$H,'حركه المخزن الرئيسي اليوميه'!$H:$H) -> 0 | M15: =+SUMIF('حركه المخزن الرئيسي اليوميه'!$F:$F,$H:$H,'حركه المخزن الرئيسي اليوميه'!$I:$I) -> 0 | N15: =+K15+L15-M15 -> 17 | O15: =+N15 -> 17 | P15: =+N15-O15 -> 0
B16: 7 | C16: الكهرباء | D16: الكهرباء | E16: مسامير + فشر بلاستك | F16: صندوق | G16: Plastic wall Plug | H16: مسامير + فشر بلاستك | I16: A-2 | J16: B000007 | K16: 2 | L16: =+SUMIF('حركه المخزن الرئيسي اليوميه'!$F:$F,$H:$H,'حركه المخزن الرئيسي اليوميه'!$H:$H) -> 0 | M16: =+SUMIF('حركه المخزن الرئيسي اليوميه'!$F:$F,$H:$H,'حركه المخزن الرئيسي اليوميه'!$I:$I) -> 0 | N16: =+K16+L16-M16 -> 2 | O16: =+N16 -> 2 | P16: =+N16-O16 -> 0
B17: 8 | C17: الكهرباء | D17: الكهرباء | E17: شريط كهرباء | F17: قطعة | G17: ELECTRIC TAP | H17: شريط كهرباء | I17: المكتب | J17: B000008 | K17: 120 | L17: =+SUMIF('حركه المخزن الرئيسي اليوميه'!$F:$F,$H:$H,'حركه المخزن الرئيسي اليوميه'!$H:$H) -> 0 | M17: =+SUMIF('حركه المخزن الرئيسي اليوميه'!$F:$F,$H:$H,'حركه المخزن الرئيسي اليوميه'!$I:$I) -> 30 | N17: =+K17+L17-M17 -> 90 | O17: =+N17 -> 90 | P17: =+N17-O17 -> 0
B18: 9 | C18: الكهرباء | D18: الكهرباء | E18: جذم كيبل 95ملى | F18: قطعة | G18: Cable shoes | H18: جذم كيبل 95ملى | I18: B-7 | J18: B000009 | K18: 0 | L18: =+SUMIF('حركه المخزن الرئيسي اليوميه'!$F:$F,$H:$H,'حركه المخزن الرئيسي اليوميه'!$H:$H) -> 0 | M18: =+SUMIF('حركه المخزن الرئيسي اليوميه'!$F:$F,$H:$H,'حركه المخزن الرئيسي اليوميه'!$I:$I) -> 0 | N18: =+K18+L18-M18 -> 0 | O18: =+N18 -> 0 | P18: =+N18-O18 -> 0
B19: 10 | C19: الكهرباء | D19: الكهرباء | E19: جزم كوابل 120 ملم | F19: قطعة | H19: جزم كوابل 120 ملم | I19: B-7 | J19: B000010 | K19: 0 | L19: =+SUMIF('حركه المخزن الرئيسي اليوميه'!$F:$F,$H:$H,'حركه المخزن الرئيسي اليوميه'!$H:$H) -> 0 | M19: =+SUMIF('حركه المخزن الرئيسي اليوميه'!$F:$F,$H:$H,'حركه المخزن الرئيسي اليوميه'!$I:$I) -> 0 | N19: =+K19+L19-M19 -> 0 | O19: =+N19 -> 0 | P19: =+N19-O19 -> 0
B20: 11 | C20: الكهرباء | D20: الكهرباء | E20: جزم كوابل 300ملي | F20: قطعة | G20: Cable shoes | H20: جزم كوابل -16- 300ملي حديد | I20: B-7 | J20: B000011 | K20: 21 | L20: =+SUMIF('حركه المخزن الرئيسي اليوميه'!$F:$F,$H:$H,'حركه المخزن الرئيسي اليوميه'!$H:$H) -> 0 | M20: =+SUMIF('حركه المخزن الرئيسي اليوميه'!$F:$F,$H:$H,'حركه المخزن الرئيسي اليوميه'!$I:$I) -> 0 | N20: =+K20+L20-M20 -> 21 | O20: =+N20 -> 21 | P20: =+N20-O20 -> 0
B21: 12 | C21: الكهرباء | D21: الكهرباء | E21: جزم كوابل 70 ملي | F21: قطعة | G21: Cable shoes | H21: جزم كوابل 70 ملي | I21: B-7 | J21: B000012 | K21: 0 | L21: =+SUMIF('حركه المخزن الرئيسي اليوميه'!$F:$F,$H:$H,'حركه المخزن الرئيسي اليوميه'!$H:$H) -> 0 | M21: =+SUMIF('حركه المخزن الرئيسي اليوميه'!$F:$F,$H:$H,'حركه المخزن الرئيسي اليوميه'!$I:$I) -> 0 | N21: =+K21+L21-M21 -> 0 | O21: =+N21 -> 0 | P21: =+N21-O21 -> 0
B22: 13 | C22: الكهرباء | D22: الكهرباء | E22: جزم كوابل تحكم | F22: قطعة | G22: Cable shoes | H22: جزم كوابل تحكم | I22: B-7 | J22: B000013 | K22: 0 | L22: =+SUMIF('حركه المخزن الرئيسي اليوميه'!$F:$F,$H:$H,'حركه المخزن الرئيسي اليوميه'!$H:$H) -> 0 | M22: =+SUMIF('حركه المخزن الرئيسي اليوميه'!$F:$F,$H:$H,'حركه المخزن الرئيسي اليوميه'!$I:$I) -> 0 | N22: =+K22+L22-M22 -> 0 | O22: =+N22 -> 0 | P22: =+N22-O22 -> 0
B23: 14 | C23: الكهرباء | D23: الكهرباء | E23: جزم كوابل | F23: قطعة | G23: Cable shoes | H23: جزم كوابل حديد 12 -150 | I23: B-7 | J23: B000014 | K23: 0 | L23: =+SUMIF('حركه المخزن الرئيسي اليوميه'!$F:$F,$H:$H,'حركه المخزن الرئيسي اليوميه'!$H:$H) -> 0 | M23: =+SUMIF('حركه المخزن الرئيسي اليوميه'!$F:$F,$H:$H,'حركه المخزن الرئيسي اليوميه'!$I:$I) -> 0 | N23: =+K23+L23-M23 -> 0 | O23: =+N23 -> 0 | P23: =+N23-O23 -> 0
B24: 15 | C24: الكهرباء | D24: الكهرباء | E24: جزم كوابل | F24: قطعة | G24: Cable shoes | H24: جزم كوابل حديد 14-185 | I24: B-7 | J24: B000015 | K24: 0 | L24: =+SUMIF('حركه المخزن الرئيسي اليوميه'!$F:$F,$H:$H,'حركه المخزن الرئيسي اليوميه'!$H:$H) -> 0 | M24: =+SUMIF('حركه المخزن الرئيسي اليوميه'!$F:$F,$H:$H,'حركه المخزن الرئيسي اليوميه'!$I:$I) -> 0 | N24: =+K24+L24-M24 -> 0 | O24: =+N24 -> 0 | P24: =+N24-O24 -> 0
B25: 16 | C25: الكهرباء | D25: الكهرباء | E25: جزم كوابل صغيره | F25: قطعة | G25: Cable shoes | H25: جزم كوابل صغيره | I25: B-7 | J25: B000016 | K25: 0 | L25: =+SUMIF('حركه المخزن الرئيسي اليوميه'!$F:$F,$H:$H,'حركه المخزن الرئيسي اليوميه'!$H:$H) -> 0 | M25: =+SUMIF('حركه المخزن الرئيسي اليوميه'!$F:$F,$H:$H,'حركه المخزن الرئيسي اليوميه'!$I:$I) -> 0 | N25: =+K25+L25-M25 -> 0 | O25: =+N25 -> 0 | P25: =+N25-O25 -> 0
B26: 17 | C26: الكهرباء | D26: الكهرباء | E26: جزم كوابل | F26: قطعة | G26: Cable shoes | H26: جزم كوابل نحاس 16-150 | I26: B-7 | J26: B000017 | K26: 0 | L26: =+SUMIF('حركه المخزن الرئيسي اليوميه'!$F:$F,$H:$H,'حركه المخزن الرئيسي اليوميه'!$H:$H) -> 0 | M26: =+SUMIF('حركه المخزن الرئيسي اليوميه'!$F:$F,$H:$H,'حركه المخزن الرئيسي اليوميه'!$I:$I) -> 0 | N26: =+K26+L26-M26 -> 0 | O26: =+N26 -> 0 | P26: =+N26-O26 -> 0
B27: 18 | C27: الكهرباء | D27: الكهرباء | E27: جزم كوابل | F27: قطعة | G27: Cable shoes | H27: جزم كوابل نحاس 16-185 | I27: B-7 | J27: B000018 | K27: 7 | L27: =+SUMIF('حركه المخزن الرئيسي اليوميه'!$F:$F,$H:$H,'حركه المخزن الرئيسي اليوميه'!$H:$H) -> 0 | M27: =+SUMIF('حركه المخزن الرئيسي اليوميه'!$F:$F,$H:$H,'حركه المخزن الرئيسي اليوميه'!$I:$I) -> 0 | N27: =+K27+L27-M27 -> 7 | O27: =+N27 -> 7 | P27: =+N27-O27 -> 0
B28: 19 | C28: الكهرباء | D28: الكهرباء | E28: جزم كوابل | F28: قطعة | G28: Cable shoes | H28: جزم كوابل نحاس D1-25 | I28: B-7 | J28: B000019 | K28: 0 | L28: =+SUMIF('حركه المخزن الرئيسي اليوميه'!$F:$F,$H:$H,'حركه المخزن الرئيسي اليوميه'!$H:$H) -> 0 | M28: =+SUMIF('حركه المخزن الرئيسي اليوميه'!$F:$F,$H:$H,'حركه المخزن الرئيسي اليوميه'!$I:$I) -> 0 | N28: =+K28+L28-M28 -> 0 | O28: =+N28 -> 0 | P28: =+N28-O28 -> 0
B29: 20 | C29: الكهرباء | D29: الكهرباء | E29: جزم كوابل 500 ملي | F29: قطعة | G29: Cable shoes | H29: جزم كوابل 500- 20 ملي حديد | I29: B-7 | J29: B000020 | K29: 4 | L29: =+SUMIF('حركه المخزن الرئيسي اليوميه'!$F:$F,$H:$H,'حركه المخزن الرئيسي اليوميه'!$H:$H) -> 0 | M29: =+SUMIF('حركه المخزن الرئيسي اليوميه'!$F:$F,$H:$H,'حركه المخزن الرئيسي اليوميه'!$I:$I) -> 0 | N29: =+K29+L29-M29 -> 4 | O29: =+N29 -> 4 | P29: =+N29-O29 -> 0
B30: 21 | C30: الكهرباء | D30: الكهرباء | E30: جزم كوابل 95 ملم | F30: قطعة | H30: جزم كوابل 95 ملم | I30: B-7 | J30: B000021 | K30: 0 | L30: =+SUMIF('حركه المخزن الرئيسي اليوميه'!$F:$F,$H:$H,'حركه المخزن الرئيسي اليوميه'!$H:$H) -> 0 | M30: =+SUMIF('حركه المخزن الرئيسي اليوميه'!$F:$F,$H:$H,'حركه المخزن الرئيسي اليوميه'!$I:$I) -> 0 | N30: =+K30+L30-M30 -> 0 | O30: =+N30 -> 0 | P30: =+N30-O30 -> 0
B31: 22 | C31: الكهرباء | D31: الكهرباء | E31: جزم كوابل 35 ملي | F31: قطعة | G31: Cable shoes | H31: جزم كوابل 35 ملي | I31: B-7 | J31: B000022 | K31: 1 | L31: =+SUMIF('حركه المخزن الرئيسي اليوميه'!$F:$F,$H:$H,'حركه المخزن الرئيسي اليوميه'!$H:$H) -> 0 | M31: =+SUMIF('حركه المخزن الرئيسي اليوميه'!$F:$F,$H:$H,'حركه المخزن الرئيسي اليوميه'!$I:$I) -> 0 | N31: =+K31+L31-M31 -> 1 | O31: =+N31 -> 1 | P31: =+N31-O31 -> 0
B32: 23 | C32: الكهرباء | D32: المصنع | E32: مراوح ثلاجة LG مربعة (3-5)وات خارجية | F32: قطعة | G32: UOTDOOR FAN | H32: مراوح ثلاجة LG مربعة (3-5)وات خارجية | I32: B-7 | J32: B000023 | K32: 1 | L32: =+SUMIF('حركه المخزن الرئيسي اليوميه'!$F:$F,$H:$H,'حركه المخزن الرئيسي اليوميه'!$H:$H) -> 0 | M32: =+SUMIF('حركه المخزن الرئيسي اليوميه'!$F:$F,$H:$H,'حركه المخزن الرئيسي اليوميه'!$I:$I) -> 0 | N32: =+K32+L32-M32 -> 1 | O32: =+N32 -> 1 | P32: =+N32-O32 -> 0
B33: 24 | C33: الكهرباء | D33: الكهرباء | E33: بريكرسكين 200 امبير | F33: قطعة | G33: Breaker 200a | H33: بريكرسكين 200 امبير | I33: C-1 | J33: B000024 | K33: 10 | L33: =+SUMIF('حركه المخزن الرئيسي اليوميه'!$F:$F,$H:$H,'حركه المخزن الرئيسي اليوميه'!$H:$H) -> 0 | M33: =+SUMIF('حركه المخزن الرئيسي اليوميه'!$F:$F,$H:$H,'حركه المخزن الرئيسي اليوميه'!$I:$I) -> 0 | N33: =+K33+L33-M33 -> 10 | O33: =+N33 -> 10 | P33: =+N33-O33 -> 0
B34: 25 | C34: الكهرباء | D34: الكهرباء | E34: جزم كوابل 16 ملي | F34: قطعة | G34: Cable shoes | H34: جزم كوابل 16 ملي | I34: A-4 | J34: B000025 | K34: 0 | L34: =+SUMIF('حركه المخزن الرئيسي اليوميه'!$F:$F,$H:$H,'حركه المخزن الرئيسي اليوميه'!$H:$H) -> 0 | M34: =+SUMIF('حركه المخزن الرئيسي اليوميه'!$F:$F,$H:$H,'حركه المخزن الرئيسي اليوميه'!$I:$I) -> 0 | N34: =+K34+L34-M34 -> 0 | O34: =+N34 -> 0 | P34: =+N34-O34 -> 0
B35: 26 | C35: الكهرباء | D35: الكهرباء | E35: جزم كوابل 25 ملي | F35: قطعة | G35: Cable shoes | H35: جزم كوابل 25 ملي | I35: A-4 | J35: B000026 | K35: 0 | L35: =+SUMIF('حركه المخزن الرئيسي اليوميه'!$F:$F,$H:$H,'حركه المخزن الرئيسي اليوميه'!$H:$H) -> 0 | M35: =+SUMIF('حركه المخزن الرئيسي اليوميه'!$F:$F,$H:$H,'حركه المخزن الرئيسي اليوميه'!$I:$I) -> 0 | N35: =+K35+L35-M35 -> 0 | O35: =+N35 -> 0 | P35: =+N35-O35 -> 0
B36: 27 | C36: الكهرباء | D36: الكهرباء | E36: جزم كوابل 50 ملي | F36: قطعة | G36: Cable shoes | H36: جزم كوابل 50 ملي | I36: A-4 | J36: B000027 | K36: 0 | L36: =+SUMIF('حركه المخزن الرئيسي اليوميه'!$F:$F,$H:$H,'حركه المخزن الرئيسي اليوميه'!$H:$H) -> 0 | M36: =+SUMIF('حركه المخزن الرئيسي اليوميه'!$F:$F,$H:$H,'حركه المخزن الرئيسي اليوميه'!$I:$I) -> 0 | N36: =+K36+L36-M36 -> 0 | O36: =+N36 -> 0 | P36: =+N36-O36 -> 0
B37: 28 | C37: الكهرباء | D37: مولدات | E37: بطارية 12 فولت | F37: قطعة | G37: BATTREY 12V | H37: بطارية 12 فولت | I37: A-4 | J37: B000028 | K37: 0 | L37: =+SUMIF('حركه المخزن الرئيسي اليوميه'!$F:$F,$H:$H,'حركه المخزن الرئيسي اليوميه'!$H:$H) -> 0 | M37: =+SUMIF('حركه المخزن الرئيسي اليوميه'!$F:$F,$H:$H,'حركه المخزن الرئيسي اليوميه'!$I:$I) -> 0 | N37: =+K37+L37-M37 -> 0 | O37: =+N37 -> 0 | P37: =+N37-O37 -> 0
B38: 29 | C38: الكهرباء | D38: المصنع | E38: وصلة حساس (الفلتر) | F38: قطعة | G38: Filter Sensor Wire | H38: وصلة حساس (الفلتر) | I38: A-6 | J38: B000029 | K38: 16 | L38: =+SUMIF('حركه المخزن الرئيسي اليوميه'!$F:$F,$H:$H,'حركه المخزن الرئيسي اليوميه'!$H:$H) -> 0 | M38: =+SUMIF('حركه المخزن الرئيسي اليوميه'!$F:$F,$H:$H,'حركه المخزن الرئيسي اليوميه'!$I:$I) -> 1 | N38: =+K38+L38-M38 -> 15 | O38: =+N38 -> 15 | P38: =+N38-O38 -> 0
B39: 30 | C39: الكهرباء | D39: المولدات | E39: حساس ضفيرة 940-996 | F39: قطعة | H39: حساس ضفيرة 940-996 | I39: A-6 | J39: B000030 | K39: 4 | L39: =+SUMIF('حركه المخزن الرئيسي اليوميه'!$F:$F,$H:$H,'حركه المخزن الرئيسي اليوميه'!$H:$H) -> 0 | M39: =+SUMIF('حركه المخزن الرئيسي اليوميه'!$F:$F,$H:$H,'حركه المخزن الرئيسي اليوميه'!$I:$I) -> 0 | N39: =+K39+L39-M39 -> 4 | O39: =+N39 -> 4 | P39: =+N39-O39 -> 0
B40: 31 | C40: الكهرباء | D40: الكهرباء | E40: تايمر 120S | F40: قطعة | G40: Timer 90s | H40: تايمر 120S | I40: A-7 | J40: B000031 | K40: 14 | L40: =+SUMIF('حركه المخزن الرئيسي اليوميه'!$F:$F,$H:$H,'حركه المخزن الرئيسي اليوميه'!$H:$H) -> 0 | M40: =+SUMIF('حركه المخزن الرئيسي اليوميه'!$F:$F,$H:$H,'حركه المخزن الرئيسي اليوميه'!$I:$I) -> 0 | N40: =+K40+L40-M40 -> 14 | O40: =+N40 -> 14 | P40: =+N40-O40 -> 0
B41: 32 | C41: الكهرباء | D41: الكهرباء | E41: تايمر 99S | F41: قطعة | G41: TIMMER 99S | H41: تايمر 99S | I41: A-7 | J41: B000032 | K41: 20 | L41: =+SUMIF('حركه المخزن الرئيسي اليوميه'!$F:$F,$H:$H,'حركه المخزن الرئيسي اليوميه'!$H:$H) -> 0 | M41: =+SUMIF('حركه المخزن الرئيسي اليوميه'!$F:$F,$H:$H,'حركه المخزن الرئيسي اليوميه'!$I:$I) -> 0 | N41: =+K41+L41-M41 -> 20 | O41: =+N41 -> 20 | P41: =+N41-O41 -> 0
B42: 33 | C42: الكهرباء | D42: الكهرباء | E42: تايمر 0.75 | F42: قطعة | G42: TIMMER 0.75 | H42: تايمر 0.75 | I42: A-7 | J42: B000033 | K42: 5 | L42: =+SUMIF('حركه المخزن الرئيسي اليوميه'!$F:$F,$H:$H,'حركه المخزن الرئيسي اليوميه'!$H:$H) -> 0 | M42: =+SUMIF('حركه المخزن الرئيسي اليوميه'!$F:$F,$H:$H,'حركه المخزن الرئيسي اليوميه'!$I:$I) -> 0 | N42: =+K42+L42-M42 -> 5 | O42: =+N42 -> 5 | P42: =+N42-O42 -> 0
B43: 34 | C43: الكهرباء | D43: الكهرباء | E43: تايمر 220V | F43: قطعة | G43: TIMMER 90 S | H43: تايمر 220V | I43: A-7 | J43: B000034 | K43: 1 | L43: =+SUMIF('حركه المخزن الرئيسي اليوميه'!$F:$F,$H:$H,'حركه المخزن الرئيسي اليوميه'!$H:$H) -> 0 | M43: =+SUMIF('حركه المخزن الرئيسي اليوميه'!$F:$F,$H:$H,'حركه المخزن الرئيسي اليوميه'!$I:$I) -> 0 | N43: =+K43+L43-M43 -> 1 | O43: =+N43 -> 1 | P43: =+N43-O43 -> 0
B44: 35 | C44: الكهرباء | D44: الكهرباء | E44: تايمر ريلي 60s | F44: قطعة | H44: تايمر ريلي 60s | I44: A-7 | J44: B000035 | K44: 8 | L44: =+SUMIF('حركه المخزن الرئيسي اليوميه'!$F:$F,$H:$H,'حركه المخزن الرئيسي اليوميه'!$H:$H) -> 0 | M44: =+SUMIF('حركه المخزن الرئيسي اليوميه'!$F:$F,$H:$H,'حركه المخزن الرئيسي اليوميه'!$I:$I) -> 0 | N44: =+K44+L44-M44 -> 8 | O44: =+N44 -> 8 | P44: =+N44-O44 -> 0
...

Sheet الرئيسي يناير 2026
M2: يناير 2026
B4: 337
E6: شركة اورشاب لتعدين الذهب
E7: المخازن 2025
K8: الكمية | R8: كرت
B9: متسلسل | C9: المخزن | D9: القسم | E9: اسم الصنف عربي | F9: الوحدة | G9: اسم الصنف E | H9: رقم الصنف | I9: الرف - الصندوق | J9: كود الصنف | K9: الرصيد الافتتاحي | L9: الوارد | M9: المنصرف | N9: الرصيد الحالي | O9: فعلي | P9: الجرد | Q9: فعلي
B10: 1 | C10: A | D10: المصنع | E10: اسيال عادية | F10: قطعة | G10: SEAL | H10: اسيال عادية | I10: A-0-2 | J10: A000001 | K10: 0 | L10: =+SUMIF('حركه المخزن الرئيسي اليوميه'!$F:$F,$H:$H,'حركه المخزن الرئيسي اليوميه'!$H:$H) -> 0 | M10: =+SUMIF('حركه المخزن الرئيسي اليوميه'!$F:$F,$H:$H,'حركه المخزن الرئيسي اليوميه'!$I:$I) -> 0 | N10: =+K10+L10-M10 -> 0 | O10: =+N10 -> 0 | P10: =+N10-O10 -> 0
B11: 2 | C11: A | D11: المصنع | E11: اوشاش ربر | F11: قطعة | G11: RUBBER GASKET | H11: اوشاش ربر مقاسات مختلفة | I11: A-0-5 | J11: A000002 | K11: 10 | L11: =+SUMIF('حركه المخزن الرئيسي اليوميه'!$F:$F,$H:$H,'حركه المخزن الرئيسي اليوميه'!$H:$H) -> 0 | M11: =+SUMIF('حركه المخزن الرئيسي اليوميه'!$F:$F,$H:$H,'حركه المخزن الرئيسي اليوميه'!$I:$I) -> 0 | N11: =+K11+L11-M11 -> 10 | O11: =+N11 -> 10 | P11: =+N11-O11 -> 0
B12: 3 | C12: A | D12: المصنع | E12: اوشاش توفلن | F12: قطعة | G12: Nylonpin | H12: اوشاش توفلن مقاسات مختلفة | I12: A-0-6 | J12: A000003 | K12: 91 | L12: =+SUMIF('حركه المخزن الرئيسي اليوميه'!$F:$F,$H:$H,'حركه المخزن الرئيسي اليوميه'!$H:$H) -> 0 | M12: =+SUMIF('حركه المخزن الرئيسي اليوميه'!$F:$F,$H:$H,'حركه المخزن الرئيسي اليوميه'!$I:$I) -> 0 | N12: =+K12+L12-M12 -> 91 | O12: =+N12 -> 91 | P12: =+N12-O12 -> 0
B13: 4 | C13: A | D13: المصنع | E13: سير B - 57 | F13: قطعة | G13: V- Belt | H13: سير B - 57 | I13: A-0-8 | J13: A000004 | K13: 0 | L13: =+SUMIF('حركه المخزن الرئيسي اليوميه'!$F:$F,$H:$H,'حركه المخزن الرئيسي اليوميه'!$H:$H) -> 0 | M13: =+SUMIF('حركه المخزن الرئيسي اليوميه'!$F:$F,$H:$H,'حركه المخزن الرئيسي اليوميه'!$I:$I) -> 0 | N13: =+K13+L13-M13 -> 0 | O13: =+N13 -> 0 | P13: =+N13-O13 -> 0
B14: 5 | C14: A | D14: المصنع | E14: تيل | F14: قطعة | G14: CIRCLIP | H14: تيل | I14: A-0-7 | J14: A000005 | K14: 12 | L14: =+SUMIF('حركه المخزن الرئيسي اليوميه'!$F:$F,$H:$H,'حركه المخزن الرئيسي اليوميه'!$H:$H) -> 0 | M14: =+SUMIF('حركه المخزن الرئيسي اليوميه'!$F:$F,$H:$H,'حركه المخزن الرئيسي اليوميه'!$I:$I) -> 0 | N14: =+K14+L14-M14 -> 12 | O14: =+N14 -> 12 | P14: =+N14-O14 -> 0
B15: 6 | C15: A | D15: الفلتر | E15: شيالات بلتة فلتر | F15: قطعة | G15: FILTER PLATE HANDLE | H15: شيالات بلتة فلتر | I15: B-6 + F-2 | J15: A000006 | K15: 59 | L15: =+SUMIF('حركه المخزن الرئيسي اليوميه'!$F:$F,$H:$H,'حركه المخزن الرئيسي اليوميه'!$H:$H) -> 0 | M15: =+SUMIF('حركه المخزن الرئيسي اليوميه'!$F:$F,$H:$H,'حركه المخزن الرئيسي اليوميه'!$I:$I) -> 0 | N15: =+K15+L15-M15 -> 59 | O15: =+N15 -> 59 | P15: =+N15-O15 -> 0
B16: 7 | C16: A | D16: الفلتر | E16: وردة فلتر | F16: قطعة | G16: FILTER PLATE WASHER | H16: وردة فلتر | I16: F-16 + F-12 | J16: A000007 | K16: 42 | L16: =+SUMIF('حركه المخزن الرئيسي اليوميه'!$F:$F,$H:$H,'حركه المخزن الرئيسي اليوميه'!$H:$H) -> 0 | M16: =+SUMIF('حركه المخزن الرئيسي اليوميه'!$F:$F,$H:$H,'حركه المخزن الرئيسي اليوميه'!$I:$I) -> 0 | N16: =+K16+L16-M16 -> 42 | O16: =+N16 -> 42 | P16: =+N16-O16 -> 0
B17: 8 | C17: A | D17: المصنع | E17: ترس عربة تحكم الفلتر ( فرول ) | F17: قطعة | G17: Impeller | H17: ترس عربة تحكم الفلتر ( فرول ) | I17: A-1 | J17: A000008 | K17: 2 | L17: =+SUMIF('حركه المخزن الرئيسي اليوميه'!$F:$F,$H:$H,'حركه المخزن الرئيسي اليوميه'!$H:$H) -> 0 | M17: =+SUMIF('حركه المخزن الرئيسي اليوميه'!$F:$F,$H:$H,'حركه المخزن الرئيسي اليوميه'!$I:$I) -> 0 | N17: =+K17+L17-M17 -> 2 | O17: =+N17 -> 2 | P17: =+N17-O17 -> 0
B18: 9 | C18: A | D18: الفلتر | E18: عربة تحكم بلنة الفلتر | F18: قطعة | G18: BULLER | H18: عربة تحكم بلنة الفلتر | I18: A-1 | J18: A000009 | K18: 6 | L18: =+SUMIF('حركه المخزن الرئيسي اليوميه'!$F:$F,$H:$H,'حركه المخزن الرئيسي اليوميه'!$H:$H) -> 0 | M18: =+SUMIF('حركه المخزن الرئيسي اليوميه'!$F:$F,$H:$H,'حركه المخزن الرئيسي اليوميه'!$I:$I) -> 0 | N18: =+K18+L18-M18 -> 6 | O18: =+N18 -> 6 | P18: =+N18-O18 -> 0
B19: 10 | C19: A | D19: المصنع | E19: بلي | F19: قطعة | G19: Bearing | H19: 6309 | I19: A-8 | J19: A000010 | K19: 3 | L19: =+SUMIF('حركه المخزن الرئيسي اليوميه'!$F:$F,$H:$H,'حركه المخزن الرئيسي اليوميه'!$H:$H) -> 0 | M19: =+SUMIF('حركه المخزن الرئيسي اليوميه'!$F:$F,$H:$H,'حركه المخزن الرئيسي اليوميه'!$I:$I) -> 0 | N19: =+K19+L19-M19 -> 3 | O19: =+N19 -> 3 | P19: =+N19-O19 -> 0
B20: 11 | C20: A | D20: المصنع | E20: بلي | F20: قطعة | G20: Bearing | H20: 30211 | I20: A-2 | J20: A000011 | K20: 47 | L20: =+SUMIF('حركه المخزن الرئيسي اليوميه'!$F:$F,$H:$H,'حركه المخزن الرئيسي اليوميه'!$H:$H) -> 0 | M20: =+SUMIF('حركه المخزن الرئيسي اليوميه'!$F:$F,$H:$H,'حركه المخزن الرئيسي اليوميه'!$I:$I) -> 0 | N20: =+K20+L20-M20 -> 47 | O20: =+N20 -> 47 | P20: =+N20-O20 -> 0
B21: 12 | C21: A | D21: المصنع | E21: بلي | F21: قطعة | G21: Bearing | H21: 30310 | I21: A-2 | J21: A000012 | K21: 27 | L21: =+SUMIF('حركه المخزن الرئيسي اليوميه'!$F:$F,$H:$H,'حركه المخزن الرئيسي اليوميه'!$H:$H) -> 0 | M21: =+SUMIF('حركه المخزن الرئيسي اليوميه'!$F:$F,$H:$H,'حركه المخزن الرئيسي اليوميه'!$I:$I) -> 0 | N21: =+K21+L21-M21 -> 27 | O21: =+N21 -> 27 | P21: =+N21-O21 -> 0
B22: 13 | C22: A | D22: المصنع | E22: بلي | F22: قطعة | G22: Bearing | H22: 6209ZZ | I22: A-2 | J22: A000013 | K22: 0 | L22: =+SUMIF('حركه المخزن الرئيسي اليوميه'!$F:$F,$H:$H,'حركه المخزن الرئيسي اليوميه'!$H:$H) -> 0 | M22: =+SUMIF('حركه المخزن الرئيسي اليوميه'!$F:$F,$H:$H,'حركه المخزن الرئيسي اليوميه'!$I:$I) -> 0 | N22: =+K22+L22-M22 -> 0 | O22: =+N22 -> 0 | P22: =+N22-O22 -> 0
B23: 14 | C23: A | D23: المصنع | E23: بلي | F23: قطعة | G23: Bearing | H23: 632 / 645 | I23: A-3 | J23: A000014 | K23: 31 | L23: =+SUMIF('حركه المخزن الرئيسي اليوميه'!$F:$F,$H:$H,'حركه المخزن الرئيسي اليوميه'!$H:$H) -> 0 | M23: =+SUMIF('حركه المخزن الرئيسي اليوميه'!$F:$F,$H:$H,'حركه المخزن الرئيسي اليوميه'!$I:$I) -> 2 | N23: =+K23+L23-M23 -> 29 | O23: =+N23 -> 29 | P23: =+N23-O23 -> 0
B24: 15 | C24: A | D24: المصنع | E24: بلي | F24: قطعة | G24: Bearing | H24: 6906 z | I24: A-14 | J24: A000015 | K24: 20 | L24: =+SUMIF('حركه المخزن الرئيسي اليوميه'!$F:$F,$H:$H,'حركه المخزن الرئيسي اليوميه'!$H:$H) -> 0 | M24: =+SUMIF('حركه المخزن الرئيسي اليوميه'!$F:$F,$H:$H,'حركه المخزن الرئيسي اليوميه'!$I:$I) -> 0 | N24: =+K24+L24-M24 -> 20 | O24: =+N24 -> 20 | P24: =+N24-O24 -> 0
B25: 16 | C25: A | D25: المصنع | E25: بلي | F25: قطعة | G25: Bearing | H25: UC210DI | I25: A-2 | J25: A000016 | K25: 7 | L25: =+SUMIF('حركه المخزن الرئيسي اليوميه'!$F:$F,$H:$H,'حركه المخزن الرئيسي اليوميه'!$H:$H) -> 0 | M25: =+SUMIF('حركه المخزن الرئيسي اليوميه'!$F:$F,$H:$H,'حركه المخزن الرئيسي اليوميه'!$I:$I) -> 0 | N25: =+K25+L25-M25 -> 7 | O25: =+N25 -> 7 | P25: =+N25-O25 -> 0
B26: 17 | C26: A | D26: مولدات | E26: مقنيتة | F26: قطعة | G26: ALTENATOR | H26: مقنيتة T.415894 | I26: A-2 | J26: A000017 | K26: 0 | L26: =+SUMIF('حركه المخزن الرئيسي اليوميه'!$F:$F,$H:$H,'حركه المخزن الرئيسي اليوميه'!$H:$H) -> 0 | M26: =+SUMIF('حركه المخزن الرئيسي اليوميه'!$F:$F,$H:$H,'حركه المخزن الرئيسي اليوميه'!$I:$I) -> 0 | N26: =+K26+L26-M26 -> 0 | O26: =+N26 -> 0 | P26: =+N26-O26 -> 0
B27: 18 | C27: A | D27: المصنع | E27: بلي | F27: قطعة | G27: Bearing | H27: 6208 | I27: A-14 | J27: A000018 | K27: 2 | L27: =+SUMIF('حركه المخزن الرئيسي اليوميه'!$F:$F,$H:$H,'حركه المخزن الرئيسي اليوميه'!$H:$H) -> 0 | M27: =+SUMIF('حركه المخزن الرئيسي اليوميه'!$F:$F,$H:$H,'حركه المخزن الرئيسي اليوميه'!$I:$I) -> 0 | N27: =+K27+L27-M27 -> 2 | O27: =+N27 -> 2 | P27: =+N27-O27 -> 0
B28: 19 | C28: A | D28: المصنع | E28: بلي | F28: قطعة | G28: Bearing | H28: 6410 | I28: A-2 | J28: A000019 | K28: 8 | L28: =+SUMIF('حركه المخزن الرئيسي اليوميه'!$F:$F,$H:$H,'حركه المخزن الرئيسي اليوميه'!$H:$H) -> 0 | M28: =+SUMIF('حركه المخزن الرئيسي اليوميه'!$F:$F,$H:$H,'حركه المخزن الرئيسي اليوميه'!$I:$I) -> 0 | N28: =+K28+L28-M28 -> 8 | O28: =+N28 -> 8 | P28: =+N28-O28 -> 0
B29: 20 | C29: A | D29: المصنع | E29: بلي | F29: قطعة | G29: Bearing | H29: 7215 | I29: A-2 | J29: A000020 | K29: 2 | L29: =+SUMIF('حركه المخزن الرئيسي اليوميه'!$F:$F,$H:$H,'حركه المخزن الرئيسي اليوميه'!$H:$H) -> 0 | M29: =+SUMIF('حركه المخزن الرئيسي اليوميه'!$F:$F,$H:$H,'حركه المخزن الرئيسي اليوميه'!$I:$I) -> 0 | N29: =+K29+L29-M29 -> 2 | O29: =+N29 -> 2 | P29: =+N29-O29 -> 0
B30: 21 | C30: A | D30: المصنع | E30: بلي | F30: قطعة | G30: Bearing | H30: 30309 | I30: A-14 | J30: A000021 | K30: 5 | L30: =+SUMIF('حركه المخزن الرئيسي اليوميه'!$F:$F,$H:$H,'حركه المخزن الرئيسي اليوميه'!$H:$H) -> 0 | M30: =+SUMIF('حركه المخزن الرئيسي اليوميه'!$F:$F,$H:$H,'حركه المخزن الرئيسي اليوميه'!$I:$I) -> 0 | N30: =+K30+L30-M30 -> 5 | O30: =+N30 -> 5 | P30: =+N30-O30 -> 0
B31: 22 | C31: A | D31: المصنع | E31: بلي | F31: قطعة | G31: Bearing | H31: 32213 | I31: A-15 | J31: A000022 | K31: 22 | L31: =+SUMIF('حركه المخزن الرئيسي اليوميه'!$F:$F,$H:$H,'حركه المخزن الرئيسي اليوميه'!$H:$H) -> 0 | M31: =+SUMIF('حركه المخزن الرئيسي اليوميه'!$F:$F,$H:$H,'حركه المخزن الرئيسي اليوميه'!$I:$I) -> 0 | N31: =+K31+L31-M31 -> 22 | O31: =+N31 -> 22 | P31: =+N31-O31 -> 0
B32: 23 | C32: A | D32: المصنع | E32: بلي | F32: قطعة | G32: Bearing | H32: 51320 | I32: A-2 | J32: A000023 | K32: 1 | L32: =+SUMIF('حركه المخزن الرئيسي اليوميه'!$F:$F,$H:$H,'حركه المخزن الرئيسي اليوميه'!$H:$H) -> 0 | M32: =+SUMIF('حركه المخزن الرئيسي اليوميه'!$F:$F,$H:$H,'حركه المخزن الرئيسي اليوميه'!$I:$I) -> 0 | N32: =+K32+L32-M32 -> 1 | O32: =+N32 -> 1 | P32: =+N32-O32 -> 0
B33: 24 | C33: A | D33: المصنع | E33: بلي | F33: قطعة | G33: Bearing | H33: ATN 1310 | I33: A-17 | J33: A000024 | K33: 68 | L33: =+SUMIF('حركه المخزن الرئيسي اليوميه'!$F:$F,$H:$H,'حركه المخزن الرئيسي اليوميه'!$H:$H) -> 0 | M33: =+SUMIF('حركه المخزن الرئيسي اليوميه'!$F:$F,$H:$H,'حركه المخزن الرئيسي اليوميه'!$I:$I) -> 0 | N33: =+K33+L33-M33 -> 68 | O33: =+N33 -> 68 | P33: =+N33-O33 -> 0
B34: 25 | C34: A | D34: المصنع | E34: بلي | F34: قطعة | G34: Bearing | H34: 305 | I34: A-3 | J34: A000025 | K34: 0 | L34: =+SUMIF('حركه المخزن الرئيسي اليوميه'!$F:$F,$H:$H,'حركه المخزن الرئيسي اليوميه'!$H:$H) -> 0 | M34: =+SUMIF('حركه المخزن الرئيسي اليوميه'!$F:$F,$H:$H,'حركه المخزن الرئيسي اليوميه'!$I:$I) -> 0 | N34: =+K34+L34-M34 -> 0 | O34: =+N34 -> 0 | P34: =+N34-O34 -> 0
B35: 26 | C35: A | D35: المصنع | E35: بلي | F35: قطعة | G35: Bearing | H35: 1316 | I35: A-3 | J35: A000026 | K35: 9 | L35: =+SUMIF('حركه المخزن الرئيسي اليوميه'!$F:$F,$H:$H,'حركه المخزن الرئيسي اليوميه'!$H:$H) -> 0 | M35: =+SUMIF('حركه المخزن الرئيسي اليوميه'!$F:$F,$H:$H,'حركه المخزن الرئيسي اليوميه'!$I:$I) -> 0 | N35: =+K35+L35-M35 -> 9 | O35: =+N35 -> 9 | P35: =+N35-O35 -> 0
B36: 27 | C36: A | D36: المصنع | E36: بلي | F36: قطعة | G36: Bearing | H36: 6204 - 2RS | I36: A-9 | J36: A000027 | K36: 204 | L36: =+SUMIF('حركه المخزن الرئيسي اليوميه'!$F:$F,$H:$H,'حركه المخزن الرئيسي اليوميه'!$H:$H) -> 0 | M36: =+SUMIF('حركه المخزن الرئيسي اليوميه'!$F:$F,$H:$H,'حركه المخزن الرئيسي اليوميه'!$I:$I) -> 8 | N36: =+K36+L36-M36 -> 196 | O36: =+N36 -> 196 | P36: =+N36-O36 -> 0
B37: 28 | C37: A | D37: المصنع | E37: بلي | F37: قطعة | G37: Bearing | H37: 6303 | I37: A-3 | J37: A000028 | K37: 0 | L37: =+SUMIF('حركه المخزن الرئيسي اليوميه'!$F:$F,$H:$H,'حركه المخزن الرئيسي اليوميه'!$H:$H) -> 0 | M37: =+SUMIF('حركه المخزن الرئيسي اليوميه'!$F:$F,$H:$H,'حركه المخزن الرئيسي اليوميه'!$I:$I) -> 0 | N37: =+K37+L37-M37 -> 0 | O37: =+N37 -> 0 | P37: =+N37-O37 -> 0
B38: 29 | C38: A | D38: المصنع | E38: بلي | F38: قطعة | G38: Bearing | H38: 6305 | I38: A-9 | J38: A000029 | K38: 63 | L38: =+SUMIF('حركه المخزن الرئيسي اليوميه'!$F:$F,$H:$H,'حركه المخزن الرئيسي اليوميه'!$H:$H) -> 0 | M38: =+SUMIF('حركه المخزن الرئيسي اليوميه'!$F:$F,$H:$H,'حركه المخزن الرئيسي اليوميه'!$I:$I) -> 0 | N38: =+K38+L38-M38 -> 63 | O38: =+N38 -> 63 | P38: =+N38-O38 -> 0
B39: 30 | C39: A | D39: المصنع | E39: بلي | F39: قطعة | G39: Bearing | H39: 6307 | I39: A-14 | J39: A000030 | K39: 18 | L39: =+SUMIF('حركه المخزن الرئيسي اليوميه'!$F:$F,$H:$H,'حركه المخزن الرئيسي اليوميه'!$H:$H) -> 0 | M39: =+SUMIF('حركه المخزن الرئيسي اليوميه'!$F:$F,$H:$H,'حركه المخزن الرئيسي اليوميه'!$I:$I) -> 4 | N39: =+K39+L39-M39 -> 14 | O39: =+N39 -> 14 | P39: =+N39-O39 -> 0
B40: 31 | C40: A | D40: المصنع | E40: بلي | F40: قطعة | G40: Bearing | H40: 30208 | I40: A-14 | J40: A000031 | K40: 7 | L40: =+SUMIF('حركه المخزن الرئيسي اليوميه'!$F:$F,$H:$H,'حركه المخزن الرئيسي اليوميه'!$H:$H) -> 0 | M40: =+SUMIF('حركه المخزن الرئيسي اليوميه'!$F:$F,$H:$H,'حركه المخزن الرئيسي اليوميه'!$I:$I) -> 0 | N40: =+K40+L40-M40 -> 7 | O40: =+N40 -> 7 | P40: =+N40-O40 -> 0
B41: 32 | C41: A | D41: المصنع | E41: بلي | F41: قطعة | G41: Bearing | H41: 55206 | I41: A-3 | J41: A000032 | K41: 39 | L41: =+SUMIF('حركه المخزن الرئيسي اليوميه'!$F:$F,$H:$H,'حركه المخزن الرئيسي اليوميه'!$H:$H) -> 0 | M41: =+SUMIF('حركه المخزن الرئيسي اليوميه'!$F:$F,$H:$H,'حركه المخزن الرئيسي اليوميه'!$I:$I) -> 0 | N41: =+K41+L41-M41 -> 39 | O41: =+N41 -> 39 | P41: =+N41-O41 -> 0
B42: 33 | C42: A | D42: المصنع | E42: بلي | F42: قطعة | G42: Bearing | H42: 6906RS | I42: A-14 | J42: A000033 | K42: 2 | L42: =+SUMIF('حركه المخزن الرئيسي اليوميه'!$F:$F,$H:$H,'حركه المخزن الرئيسي اليوميه'!$H:$H) -> 0 | M42: =+SUMIF('حركه المخزن الرئيسي اليوميه'!$F:$F,$H:$H,'حركه المخزن الرئيسي اليوميه'!$I:$I) -> 0 | N42: =+K42+L42-M42 -> 2 | O42: =+N42 -> 2 | P42: =+N42-O42 -> 0
B43: 34 | C43: A | D43: المصنع | E43: بلي | F43: قطعة | H43: RN 206E | I43: A-14 | J43: A000034 | K43: 8 | L43: =+SUMIF('حركه المخزن الرئيسي اليوميه'!$F:$F,$H:$H,'حركه المخزن الرئيسي اليوميه'!$H:$H) -> 0 | M43: =+SUMIF('حركه المخزن الرئيسي اليوميه'!$F:$F,$H:$H,'حركه المخزن الرئيسي اليوميه'!$I:$I) -> 0 | N43: =+K43+L43-M43 -> 8 | O43: =+N43 -> 8 | P43: =+N43-O43 -> 0
...

Sheet حركه المخزن الرئيسي اليوميه
F2: شركة أورشاب لتعدين الذهب
F3: تقرير المخزن يناير 2026
H4: الكمبة
B5: اسم المخزن | C5: رقم سند الصرف/المنفست | D5: كود الصنف | E5: اسم الصنف | F5: رقم الصنف | G5: اتاريخ | H5: وارد | I5: منصرف | J5: اسم المستلم | K5: اسم المسلم ( الواردات ) | L5: جهة الاستخدام | M5: ملاحظات
B6: الفرعي | C6: 25493 | D6: C000035 | E6: DN 100/16 بلف عادي | F6: DN 100/16 بلف عادي | G6: 46023 | I6: 1 | J6: عصام حمد | L6: سايكلون الطواحين
B7: الرئيسي | C7: 25493 | D7: A000392 | E7: C 2427 Li سير | F7: C 2427 Li | G7: 46023 | I7: 4 | J7: عصام حمد | L7: طلمبة الفلتر
B8: الرئيسي | C8: 25493 | D8: A000677 | E8: 2" كلبسات سير | F8: 2" كلبسات سير | G8: 46023 | I8: 7 | J8: عصام حمد | L8: سير الفلتر
B9: الفرعي | C9: 25493 | D9: C000187 | E9: خرطوش 1بوصة (عب الواطه) | F9: خرطوش 1بوصة (عب الواطه) | G9: 46023 | I9: 1 | J9: عصام حمد | L9: السكن | XFD9: ي
B10: الفرعي | C10: 25493 | D10: C000164 | E10: لستك درداقه مع عجل حديد | F10: لستك درداقه مع عجل حديد | G10: 46023 | I10: 2 | J10: عصام حمد | L10: الصيانة | XFD10: ي
B11: الرئيسي | C11: 25493 | D11: A000472 | E11: 1.1\2-3\4 تي حديد مخفض | F11: 1.1\2-3\4 تي حديد مخفض | G11: 46023 | I11: 1 | J11: عصام حمد | L11: التنوكة
B12: الكهرباء | C12: 25494 | D12: B000029 | E12: وصلة حساس (الفلتر) | F12: وصلة حساس (الفلتر) | G12: 46023 | I12: 1 | J12: مهند يوسف | L12: الفلتر | XFD12: ي
B13: الرئيسي | C13: 25494 | D13: A000999 | E13: جهاز تامين سيور المصنع | F13: جهاز تامين سيور المصنع | G13: 46023 | I13: 1 | J13: مهند يوسف | L13: سير الفلتر
B14: الرئيسي | C14: 25494 | D14: A000675 | E14: ترنكات بلاستيك 2سم / 25*25 | F14: ترنكات بلاستيك 2سم / 25*25 | G14: 46023 | I14: 3 | J14: مهند يوسف | L14: الفلتر
B15: الكهرباء | C15: 25494 | D15: B000165 | E15: لمبه بيان عادي احمر | F15: لمبه بيان عادي احمر | G15: 46023 | I15: 1 | J15: مهند يوسف | L15: الفلتر
B16: الرئيسي | C16: 25495 | D16: A000027 | E16: بلي | F16: 6204 - 2RS | G16: 46024 | I16: 4 | J16: عصام حمد | L16: الكمبرسون
